2021-05-14 10:33:53,273 - gravity_core.wlogger - ERROR - Ошибка в работе оператора!
2021-05-14 10:33:53,275 - gravity_core.wlogger - ERROR - Traceback (most recent call last):
  File "wlauncher.py", line 59, in _start
    self.gravity_core.work()
  File "/home/watchman/Gravity_core_export/gravity_core/wengine.py", line 1187, in work
    self.operate_skud_stream()
  File "/home/watchman/Gravity_core_export/gravity_core/wengine.py", line 1130, in operate_skud_stream
    data = self.get_skud_data(self.sock)
  File "/home/watchman/Gravity_core_export/gravity_core/wengine.py", line 1151, in get_skud_data
    data = data.decode()
AttributeError: 'NoneType' object has no attribute 'decode'

2021-05-14 16:43:57,089 - gravity_core.wlogger - ERROR - Ошибка в работе оператора!
2021-05-14 16:43:57,092 - gravity_core.wlogger - ERROR - Traceback (most recent call last):
  File "wlauncher.py", line 59, in _start
    self.gravity_core.work()
  File "/home/watchman/Gravity_core_export/gravity_core/wengine.py", line 1187, in work
    self.operate_skud_stream()
  File "/home/watchman/Gravity_core_export/gravity_core/wengine.py", line 1130, in operate_skud_stream
    data = self.get_skud_data(self.sock)
  File "/home/watchman/Gravity_core_export/gravity_core/wengine.py", line 1151, in get_skud_data
    data = data.decode()
AttributeError: 'NoneType' object has no attribute 'decode'

2021-05-14 16:48:31,366 - gravity_core.wlogger - ERROR - Ошибка в работе оператора!
2021-05-14 16:48:31,368 - gravity_core.wlogger - ERROR - Traceback (most recent call last):
  File "wlauncher.py", line 59, in _start
    self.gravity_core.work()
  File "/home/watchman/Gravity_core_export/gravity_core/wengine.py", line 1195, in work
    self.operate_skud_stream()
  File "/home/watchman/Gravity_core_export/gravity_core/wengine.py", line 1138, in operate_skud_stream
    data = self.get_skud_data(self.sock)
  File "/home/watchman/Gravity_core_export/gravity_core/wengine.py", line 1159, in get_skud_data
    data = data.decode()
AttributeError: 'NoneType' object has no attribute 'decode'

2021-05-14 16:57:38,961 - gravity_core.wlogger - ERROR - Ошибка в работе оператора!
2021-05-14 16:57:38,963 - gravity_core.wlogger - ERROR - Traceback (most recent call last):
  File "wlauncher.py", line 59, in _start
    self.gravity_core.work()
  File "/home/watchman/Gravity_core_export/gravity_core/wengine.py", line 1195, in work
    self.operate_skud_stream()
  File "/home/watchman/Gravity_core_export/gravity_core/wengine.py", line 1138, in operate_skud_stream
    data = self.get_skud_data(self.sock)
  File "/home/watchman/Gravity_core_export/gravity_core/wengine.py", line 1159, in get_skud_data
    data = data.decode()
AttributeError: 'NoneType' object has no attribute 'decode'

2021-05-14 16:57:52,563 - gravity_core.wlogger - ERROR - Ошибка в работе оператора!
2021-05-14 16:57:52,564 - gravity_core.wlogger - ERROR - Traceback (most recent call last):
  File "wlauncher.py", line 59, in _start
    self.gravity_core.work()
  File "/home/watchman/Gravity_core_export/gravity_core/wengine.py", line 1195, in work
    self.operate_skud_stream()
  File "/home/watchman/Gravity_core_export/gravity_core/wengine.py", line 1138, in operate_skud_stream
    data = self.get_skud_data(self.sock)
  File "/home/watchman/Gravity_core_export/gravity_core/wengine.py", line 1159, in get_skud_data
    data = data.decode()
AttributeError: 'NoneType' object has no attribute 'decode'

2021-05-14 16:58:24,737 - gravity_core.wlogger - ERROR - Ошибка в работе оператора!
2021-05-14 16:58:24,738 - gravity_core.wlogger - ERROR - Traceback (most recent call last):
  File "wlauncher.py", line 59, in _start
    self.gravity_core.work()
  File "/home/watchman/Gravity_core_export/gravity_core/wengine.py", line 1195, in work
    self.operate_skud_stream()
  File "/home/watchman/Gravity_core_export/gravity_core/wengine.py", line 1138, in operate_skud_stream
    data = self.get_skud_data(self.sock)
  File "/home/watchman/Gravity_core_export/gravity_core/wengine.py", line 1159, in get_skud_data
    data = data.decode()
AttributeError: 'NoneType' object has no attribute 'decode'

2021-05-14 17:01:09,915 - gravity_core.wlogger - ERROR - Ошибка в работе оператора!
2021-05-14 17:01:09,916 - gravity_core.wlogger - ERROR - Traceback (most recent call last):
  File "wlauncher.py", line 59, in _start
    self.gravity_core.work()
  File "/home/watchman/Gravity_core_export/gravity_core/wengine.py", line 1195, in work
    self.operate_skud_stream()
  File "/home/watchman/Gravity_core_export/gravity_core/wengine.py", line 1138, in operate_skud_stream
    data = self.get_skud_data(self.sock)
  File "/home/watchman/Gravity_core_export/gravity_core/wengine.py", line 1159, in get_skud_data
    data = data.decode()
AttributeError: 'NoneType' object has no attribute 'decode'

2021-05-14 17:02:01,497 - gravity_core.wlogger - ERROR - Ошибка в работе оператора!
2021-05-14 17:02:01,498 - gravity_core.wlogger - ERROR - Traceback (most recent call last):
  File "wlauncher.py", line 59, in _start
    self.gravity_core.work()
  File "/home/watchman/Gravity_core_export/gravity_core/wengine.py", line 1195, in work
    self.operate_skud_stream()
  File "/home/watchman/Gravity_core_export/gravity_core/wengine.py", line 1138, in operate_skud_stream
    data = self.get_skud_data(self.sock)
  File "/home/watchman/Gravity_core_export/gravity_core/wengine.py", line 1159, in get_skud_data
    data = data.decode()
AttributeError: 'NoneType' object has no attribute 'decode'

2021-05-14 17:08:16,296 - gravity_core.wlogger - ERROR - Ошибка в работе оператора!
2021-05-14 17:08:16,298 - gravity_core.wlogger - ERROR - Traceback (most recent call last):
  File "wlauncher.py", line 59, in _start
    self.gravity_core.work()
  File "/home/watchman/Gravity_core_export/gravity_core/wengine.py", line 1195, in work
    self.operate_skud_stream()
  File "/home/watchman/Gravity_core_export/gravity_core/wengine.py", line 1138, in operate_skud_stream
    data = self.get_skud_data(self.sock)
  File "/home/watchman/Gravity_core_export/gravity_core/wengine.py", line 1159, in get_skud_data
    data = data.decode()
AttributeError: 'NoneType' object has no attribute 'decode'

2021-05-14 17:15:30,331 - gravity_core.wlogger - ERROR - Ошибка в работе оператора!
2021-05-14 17:15:30,333 - gravity_core.wlogger - ERROR - Traceback (most recent call last):
  File "wlauncher.py", line 59, in _start
    self.gravity_core.work()
  File "/home/watchman/Gravity_core_export/gravity_core/wengine.py", line 1195, in work
    self.operate_skud_stream()
  File "/home/watchman/Gravity_core_export/gravity_core/wengine.py", line 1138, in operate_skud_stream
    data = self.get_skud_data(self.sock)
  File "/home/watchman/Gravity_core_export/gravity_core/wengine.py", line 1159, in get_skud_data
    data = data.decode()
AttributeError: 'NoneType' object has no attribute 'decode'

2021-05-14 17:34:01,306 - gravity_core.wlogger - ERROR - Ошибка в работе оператора!
2021-05-14 17:34:01,307 - gravity_core.wlogger - ERROR - Traceback (most recent call last):
  File "wlauncher.py", line 59, in _start
    self.gravity_core.work()
  File "/home/watchman/Gravity_core_export/gravity_core/wengine.py", line 1195, in work
    self.operate_skud_stream()
  File "/home/watchman/Gravity_core_export/gravity_core/wengine.py", line 1138, in operate_skud_stream
    data = self.get_skud_data(self.sock)
  File "/home/watchman/Gravity_core_export/gravity_core/wengine.py", line 1159, in get_skud_data
    data = data.decode()
AttributeError: 'NoneType' object has no attribute 'decode'

2021-05-14 17:35:18,899 - gravity_core.wlogger - ERROR - Ошибка в работе оператора!
2021-05-14 17:35:18,900 - gravity_core.wlogger - ERROR - Traceback (most recent call last):
  File "wlauncher.py", line 59, in _start
    self.gravity_core.work()
  File "/home/watchman/Gravity_core_export/gravity_core/wengine.py", line 1195, in work
    self.operate_skud_stream()
  File "/home/watchman/Gravity_core_export/gravity_core/wengine.py", line 1138, in operate_skud_stream
    data = self.get_skud_data(self.sock)
  File "/home/watchman/Gravity_core_export/gravity_core/wengine.py", line 1159, in get_skud_data
    data = data.decode()
AttributeError: 'NoneType' object has no attribute 'decode'

2021-05-14 17:38:52,250 - gravity_core.wlogger - ERROR - Traceback (most recent call last):
  File "/usr/lib/python3/dist-packages/serial/serialposix.py", line 265, in open
    self.fd = os.open(self.portstr, os.O_RDWR | os.O_NOCTTY | os.O_NONBLOCK)
PermissionError: [Errno 13] Permission denied: '/dev/ttyS4'

During handling of the above exception, another exception occurred:

Traceback (most recent call last):
  File "/home/watchman/Gravity_core_export/gravity_core/wengine.py", line 84, in make_cps_connection
    self.cps.start()
  File "/home/watchman/.local/lib/python3.8/site-packages/portdatasplitter/main.py", line 42, in start
    self._mainloop()
  File "/home/watchman/.local/lib/python3.8/site-packages/portdatasplitter/main.py", line 94, in _mainloop
    self.port = Serial(self.port_name, bytesize=8, parity='N', stopbits=1, timeout=1, baudrate=9600)
  File "/usr/lib/python3/dist-packages/serial/serialutil.py", line 240, in __init__
    self.open()
  File "/usr/lib/python3/dist-packages/serial/serialposix.py", line 268, in open
    raise SerialException(msg.errno, "could not open port {}: {}".format(self._port, msg))
serial.serialutil.SerialException: [Errno 13] could not open port /dev/ttyS4: [Errno 13] Permission denied: '/dev/ttyS4'

2021-05-14 17:38:57,256 - gravity_core.wlogger - ERROR - Traceback (most recent call last):
  File "/home/watchman/Gravity_core_export/gravity_core/wengine.py", line 84, in make_cps_connection
    self.cps.start()
  File "/home/watchman/.local/lib/python3.8/site-packages/portdatasplitter/main.py", line 36, in start
    self.create_server(self.server_ip, self.server_port)
  File "/home/watchman/.local/lib/python3.8/site-packages/portdatasplitter/main.py", line 55, in create_server
    self.serv.bind((ip, port))
OSError: [Errno 98] Address already in use

2021-05-14 18:06:36,451 - gravity_core.wlogger - ERROR - Ошибка в работе оператора!
2021-05-14 18:06:36,452 - gravity_core.wlogger - ERROR - Traceback (most recent call last):
  File "wlauncher.py", line 59, in _start
    self.gravity_core.work()
  File "/home/watchman/Gravity_core_export/gravity_core/wengine.py", line 1195, in work
    self.operate_skud_stream()
  File "/home/watchman/Gravity_core_export/gravity_core/wengine.py", line 1138, in operate_skud_stream
    data = self.get_skud_data(self.sock)
  File "/home/watchman/Gravity_core_export/gravity_core/wengine.py", line 1159, in get_skud_data
    data = data.decode()
AttributeError: 'NoneType' object has no attribute 'decode'

2021-05-14 18:10:14,668 - gravity_core.wlogger - ERROR - Ошибка в работе оператора!
2021-05-14 18:10:14,670 - gravity_core.wlogger - ERROR - Traceback (most recent call last):
  File "wlauncher.py", line 59, in _start
    self.gravity_core.work()
  File "/home/watchman/Gravity_core_export/gravity_core/wengine.py", line 1196, in work
    self.operate_skud_stream()
  File "/home/watchman/Gravity_core_export/gravity_core/wengine.py", line 1139, in operate_skud_stream
    data = self.get_skud_data(self.sock)
  File "/home/watchman/Gravity_core_export/gravity_core/wengine.py", line 1160, in get_skud_data
    data = data.decode()
AttributeError: 'NoneType' object has no attribute 'decode'

