2021-04-23 15:23:49,654 - gravity_core.wlogger - ERROR - Traceback (most recent call last):
  File "/home/qodex/.local/lib/python3.8/site-packages/serial/serialposix.py", line 322, in open
    self.fd = os.open(self.portstr, os.O_RDWR | os.O_NOCTTY | os.O_NONBLOCK)
PermissionError: [Errno 13] Permission denied: '/dev/ttyS5'

During handling of the above exception, another exception occurred:

Traceback (most recent call last):
  File "/home/qodex/Gravity_core_export/gravity_core/wengine.py", line 69, in make_cps_connection
    self.cps.start()
  File "/home/qodex/.local/lib/python3.8/site-packages/portdatasplitter/main.py", line 42, in start
    self._mainloop()
  File "/home/qodex/.local/lib/python3.8/site-packages/portdatasplitter/main.py", line 94, in _mainloop
    self.port = Serial(self.port_name, bytesize=8, parity='N', stopbits=1, timeout=1, baudrate=9600)
  File "/home/qodex/.local/lib/python3.8/site-packages/serial/serialutil.py", line 244, in __init__
    self.open()
  File "/home/qodex/.local/lib/python3.8/site-packages/serial/serialposix.py", line 325, in open
    raise SerialException(msg.errno, "could not open port {}: {}".format(self._port, msg))
serial.serialutil.SerialException: [Errno 13] could not open port /dev/ttyS5: [Errno 13] Permission denied: '/dev/ttyS5'

2021-04-23 15:23:57,975 - gravity_core.wlogger - ERROR - Traceback (most recent call last):
  File "/home/qodex/Gravity_core_export/gravity_core/wengine.py", line 69, in make_cps_connection
    self.cps.start()
  File "/home/qodex/.local/lib/python3.8/site-packages/portdatasplitter/main.py", line 36, in start
    self.create_server(self.server_ip, self.server_port)
  File "/home/qodex/.local/lib/python3.8/site-packages/portdatasplitter/main.py", line 55, in create_server
    self.serv.bind((ip, port))
OSError: [Errno 98] Address already in use

2021-04-23 15:24:02,982 - gravity_core.wlogger - ERROR - Traceback (most recent call last):
  File "/home/qodex/Gravity_core_export/gravity_core/wengine.py", line 69, in make_cps_connection
    self.cps.start()
  File "/home/qodex/.local/lib/python3.8/site-packages/portdatasplitter/main.py", line 36, in start
    self.create_server(self.server_ip, self.server_port)
  File "/home/qodex/.local/lib/python3.8/site-packages/portdatasplitter/main.py", line 55, in create_server
    self.serv.bind((ip, port))
OSError: [Errno 98] Address already in use

2021-04-23 15:24:07,986 - gravity_core.wlogger - ERROR - Traceback (most recent call last):
  File "/home/qodex/Gravity_core_export/gravity_core/wengine.py", line 69, in make_cps_connection
    self.cps.start()
  File "/home/qodex/.local/lib/python3.8/site-packages/portdatasplitter/main.py", line 36, in start
    self.create_server(self.server_ip, self.server_port)
  File "/home/qodex/.local/lib/python3.8/site-packages/portdatasplitter/main.py", line 55, in create_server
    self.serv.bind((ip, port))
OSError: [Errno 98] Address already in use

2021-04-23 15:24:10,454 - gravity_core.wlogger - ERROR - Traceback (most recent call last):
  File "/home/qodex/Gravity_core_export/gravity_core/wengine.py", line 685, in send_act
    sig_funcs.send_json_reports(self.sqlshell, self.wserver_client, self.poligon_id,
  File "/home/qodex/Gravity_core_export/gravity_core/reports/signall_reports_funcs.py", line 64, in send_json_reports
    save_json_report(sqlshell, poligon_id, table, filename)
  File "/home/qodex/Gravity_core_export/gravity_core/reports/signall_reports_funcs.py", line 23, in save_json_report
    save_json(records_list, filename, poligon_id)
  File "/home/qodex/Gravity_core_export/gravity_core/reports/signall_reports_funcs.py", line 53, in save_json
    with open(filepath, 'w') as fobj:
FileNotFoundError: [Errno 2] No such file or directory: '/home/qodex/Gravity_core_export/gravity_core/reports/json_reports/json_clients'

2021-04-23 15:24:12,989 - gravity_core.wlogger - ERROR - Traceback (most recent call last):
  File "/home/qodex/Gravity_core_export/gravity_core/wengine.py", line 69, in make_cps_connection
    self.cps.start()
  File "/home/qodex/.local/lib/python3.8/site-packages/portdatasplitter/main.py", line 36, in start
    self.create_server(self.server_ip, self.server_port)
  File "/home/qodex/.local/lib/python3.8/site-packages/portdatasplitter/main.py", line 55, in create_server
    self.serv.bind((ip, port))
OSError: [Errno 98] Address already in use

2021-04-23 15:24:17,994 - gravity_core.wlogger - ERROR - Traceback (most recent call last):
  File "/home/qodex/Gravity_core_export/gravity_core/wengine.py", line 69, in make_cps_connection
    self.cps.start()
  File "/home/qodex/.local/lib/python3.8/site-packages/portdatasplitter/main.py", line 36, in start
    self.create_server(self.server_ip, self.server_port)
  File "/home/qodex/.local/lib/python3.8/site-packages/portdatasplitter/main.py", line 55, in create_server
    self.serv.bind((ip, port))
OSError: [Errno 98] Address already in use

2021-04-23 15:24:23,001 - gravity_core.wlogger - ERROR - Traceback (most recent call last):
  File "/home/qodex/Gravity_core_export/gravity_core/wengine.py", line 69, in make_cps_connection
    self.cps.start()
  File "/home/qodex/.local/lib/python3.8/site-packages/portdatasplitter/main.py", line 36, in start
    self.create_server(self.server_ip, self.server_port)
  File "/home/qodex/.local/lib/python3.8/site-packages/portdatasplitter/main.py", line 55, in create_server
    self.serv.bind((ip, port))
OSError: [Errno 98] Address already in use

