2021-05-04 06:26:18,786 - gravity_core.wlogger - ERROR - Traceback (most recent call last):
  File "/home/qodex/Gravity_core_export/gravity_core/wlistener.py", line 102, in broadcastMsgSend
    conn.send(msg)
BrokenPipeError: [Errno 32] Broken pipe

2021-05-04 06:26:24,303 - gravity_core.wlogger - ERROR - Traceback (most recent call last):
  File "/home/qodex/Gravity_core_export/gravity_core/wlistener.py", line 102, in broadcastMsgSend
    conn.send(msg)
BrokenPipeError: [Errno 32] Broken pipe

2021-05-04 06:26:25,284 - gravity_core.wlogger - ERROR - Traceback (most recent call last):
  File "/home/qodex/Gravity_core_export/gravity_core/wlistener.py", line 102, in broadcastMsgSend
    conn.send(msg)
BrokenPipeError: [Errno 32] Broken pipe

2021-05-04 06:34:55,138 - gravity_core.wlogger - ERROR - Traceback (most recent call last):
  File "/home/qodex/Gravity_core_export/gravity_core/wengine.py", line 76, in make_cps_connection
    self.cps.start()
  File "/home/qodex/.local/lib/python3.8/site-packages/portdatasplitter/main.py", line 42, in start
    self._mainloop()
  File "/home/qodex/.local/lib/python3.8/site-packages/portdatasplitter/main.py", line 96, in _mainloop
    data = self.port.readline()
  File "/home/qodex/.local/lib/python3.8/site-packages/serial/serialposix.py", line 560, in read
    raise PortNotOpenError()
serial.serialutil.PortNotOpenError: Attempting to use a port that is not open

2021-05-04 06:35:00,146 - gravity_core.wlogger - ERROR - Traceback (most recent call last):
  File "/home/qodex/Gravity_core_export/gravity_core/wengine.py", line 76, in make_cps_connection
    self.cps.start()
  File "/home/qodex/.local/lib/python3.8/site-packages/portdatasplitter/main.py", line 36, in start
    self.create_server(self.server_ip, self.server_port)
  File "/home/qodex/.local/lib/python3.8/site-packages/portdatasplitter/main.py", line 55, in create_server
    self.serv.bind((ip, port))
OSError: [Errno 98] Address already in use

2021-05-04 06:35:05,154 - gravity_core.wlogger - ERROR - Traceback (most recent call last):
  File "/home/qodex/Gravity_core_export/gravity_core/wengine.py", line 76, in make_cps_connection
    self.cps.start()
  File "/home/qodex/.local/lib/python3.8/site-packages/portdatasplitter/main.py", line 36, in start
    self.create_server(self.server_ip, self.server_port)
  File "/home/qodex/.local/lib/python3.8/site-packages/portdatasplitter/main.py", line 55, in create_server
    self.serv.bind((ip, port))
OSError: [Errno 98] Address already in use

2021-05-04 06:35:10,158 - gravity_core.wlogger - ERROR - Traceback (most recent call last):
  File "/home/qodex/Gravity_core_export/gravity_core/wengine.py", line 76, in make_cps_connection
    self.cps.start()
  File "/home/qodex/.local/lib/python3.8/site-packages/portdatasplitter/main.py", line 36, in start
    self.create_server(self.server_ip, self.server_port)
  File "/home/qodex/.local/lib/python3.8/site-packages/portdatasplitter/main.py", line 55, in create_server
    self.serv.bind((ip, port))
OSError: [Errno 98] Address already in use

2021-05-04 06:35:15,167 - gravity_core.wlogger - ERROR - Traceback (most recent call last):
  File "/home/qodex/Gravity_core_export/gravity_core/wengine.py", line 76, in make_cps_connection
    self.cps.start()
  File "/home/qodex/.local/lib/python3.8/site-packages/portdatasplitter/main.py", line 36, in start
    self.create_server(self.server_ip, self.server_port)
  File "/home/qodex/.local/lib/python3.8/site-packages/portdatasplitter/main.py", line 55, in create_server
    self.serv.bind((ip, port))
OSError: [Errno 98] Address already in use

2021-05-04 06:35:20,175 - gravity_core.wlogger - ERROR - Traceback (most recent call last):
  File "/home/qodex/Gravity_core_export/gravity_core/wengine.py", line 76, in make_cps_connection
    self.cps.start()
  File "/home/qodex/.local/lib/python3.8/site-packages/portdatasplitter/main.py", line 36, in start
    self.create_server(self.server_ip, self.server_port)
  File "/home/qodex/.local/lib/python3.8/site-packages/portdatasplitter/main.py", line 55, in create_server
    self.serv.bind((ip, port))
OSError: [Errno 98] Address already in use

2021-05-04 06:35:25,182 - gravity_core.wlogger - ERROR - Traceback (most recent call last):
  File "/home/qodex/Gravity_core_export/gravity_core/wengine.py", line 76, in make_cps_connection
    self.cps.start()
  File "/home/qodex/.local/lib/python3.8/site-packages/portdatasplitter/main.py", line 36, in start
    self.create_server(self.server_ip, self.server_port)
  File "/home/qodex/.local/lib/python3.8/site-packages/portdatasplitter/main.py", line 55, in create_server
    self.serv.bind((ip, port))
OSError: [Errno 98] Address already in use

2021-05-04 06:35:30,190 - gravity_core.wlogger - ERROR - Traceback (most recent call last):
  File "/home/qodex/Gravity_core_export/gravity_core/wengine.py", line 76, in make_cps_connection
    self.cps.start()
  File "/home/qodex/.local/lib/python3.8/site-packages/portdatasplitter/main.py", line 36, in start
    self.create_server(self.server_ip, self.server_port)
  File "/home/qodex/.local/lib/python3.8/site-packages/portdatasplitter/main.py", line 55, in create_server
    self.serv.bind((ip, port))
OSError: [Errno 98] Address already in use

2021-05-04 06:35:35,199 - gravity_core.wlogger - ERROR - Traceback (most recent call last):
  File "/home/qodex/Gravity_core_export/gravity_core/wengine.py", line 76, in make_cps_connection
    self.cps.start()
  File "/home/qodex/.local/lib/python3.8/site-packages/portdatasplitter/main.py", line 36, in start
    self.create_server(self.server_ip, self.server_port)
  File "/home/qodex/.local/lib/python3.8/site-packages/portdatasplitter/main.py", line 55, in create_server
    self.serv.bind((ip, port))
OSError: [Errno 98] Address already in use

2021-05-04 06:35:40,208 - gravity_core.wlogger - ERROR - Traceback (most recent call last):
  File "/home/qodex/Gravity_core_export/gravity_core/wengine.py", line 76, in make_cps_connection
    self.cps.start()
  File "/home/qodex/.local/lib/python3.8/site-packages/portdatasplitter/main.py", line 36, in start
    self.create_server(self.server_ip, self.server_port)
  File "/home/qodex/.local/lib/python3.8/site-packages/portdatasplitter/main.py", line 55, in create_server
    self.serv.bind((ip, port))
OSError: [Errno 98] Address already in use

2021-05-04 06:35:45,217 - gravity_core.wlogger - ERROR - Traceback (most recent call last):
  File "/home/qodex/Gravity_core_export/gravity_core/wengine.py", line 76, in make_cps_connection
    self.cps.start()
  File "/home/qodex/.local/lib/python3.8/site-packages/portdatasplitter/main.py", line 36, in start
    self.create_server(self.server_ip, self.server_port)
  File "/home/qodex/.local/lib/python3.8/site-packages/portdatasplitter/main.py", line 55, in create_server
    self.serv.bind((ip, port))
OSError: [Errno 98] Address already in use

2021-05-04 06:35:50,221 - gravity_core.wlogger - ERROR - Traceback (most recent call last):
  File "/home/qodex/Gravity_core_export/gravity_core/wengine.py", line 76, in make_cps_connection
    self.cps.start()
  File "/home/qodex/.local/lib/python3.8/site-packages/portdatasplitter/main.py", line 36, in start
    self.create_server(self.server_ip, self.server_port)
  File "/home/qodex/.local/lib/python3.8/site-packages/portdatasplitter/main.py", line 55, in create_server
    self.serv.bind((ip, port))
OSError: [Errno 98] Address already in use

2021-05-04 06:35:55,229 - gravity_core.wlogger - ERROR - Traceback (most recent call last):
  File "/home/qodex/Gravity_core_export/gravity_core/wengine.py", line 76, in make_cps_connection
    self.cps.start()
  File "/home/qodex/.local/lib/python3.8/site-packages/portdatasplitter/main.py", line 36, in start
    self.create_server(self.server_ip, self.server_port)
  File "/home/qodex/.local/lib/python3.8/site-packages/portdatasplitter/main.py", line 55, in create_server
    self.serv.bind((ip, port))
OSError: [Errno 98] Address already in use

2021-05-04 06:36:00,237 - gravity_core.wlogger - ERROR - Traceback (most recent call last):
  File "/home/qodex/Gravity_core_export/gravity_core/wengine.py", line 76, in make_cps_connection
    self.cps.start()
  File "/home/qodex/.local/lib/python3.8/site-packages/portdatasplitter/main.py", line 36, in start
    self.create_server(self.server_ip, self.server_port)
  File "/home/qodex/.local/lib/python3.8/site-packages/portdatasplitter/main.py", line 55, in create_server
    self.serv.bind((ip, port))
OSError: [Errno 98] Address already in use

2021-05-04 06:36:05,246 - gravity_core.wlogger - ERROR - Traceback (most recent call last):
  File "/home/qodex/Gravity_core_export/gravity_core/wengine.py", line 76, in make_cps_connection
    self.cps.start()
  File "/home/qodex/.local/lib/python3.8/site-packages/portdatasplitter/main.py", line 36, in start
    self.create_server(self.server_ip, self.server_port)
  File "/home/qodex/.local/lib/python3.8/site-packages/portdatasplitter/main.py", line 55, in create_server
    self.serv.bind((ip, port))
OSError: [Errno 98] Address already in use

2021-05-04 06:36:10,255 - gravity_core.wlogger - ERROR - Traceback (most recent call last):
  File "/home/qodex/Gravity_core_export/gravity_core/wengine.py", line 76, in make_cps_connection
    self.cps.start()
  File "/home/qodex/.local/lib/python3.8/site-packages/portdatasplitter/main.py", line 36, in start
    self.create_server(self.server_ip, self.server_port)
  File "/home/qodex/.local/lib/python3.8/site-packages/portdatasplitter/main.py", line 55, in create_server
    self.serv.bind((ip, port))
OSError: [Errno 98] Address already in use

2021-05-04 06:36:15,263 - gravity_core.wlogger - ERROR - Traceback (most recent call last):
  File "/home/qodex/Gravity_core_export/gravity_core/wengine.py", line 76, in make_cps_connection
    self.cps.start()
  File "/home/qodex/.local/lib/python3.8/site-packages/portdatasplitter/main.py", line 36, in start
    self.create_server(self.server_ip, self.server_port)
  File "/home/qodex/.local/lib/python3.8/site-packages/portdatasplitter/main.py", line 55, in create_server
    self.serv.bind((ip, port))
OSError: [Errno 98] Address already in use

2021-05-04 06:36:20,272 - gravity_core.wlogger - ERROR - Traceback (most recent call last):
  File "/home/qodex/Gravity_core_export/gravity_core/wengine.py", line 76, in make_cps_connection
    self.cps.start()
  File "/home/qodex/.local/lib/python3.8/site-packages/portdatasplitter/main.py", line 36, in start
    self.create_server(self.server_ip, self.server_port)
  File "/home/qodex/.local/lib/python3.8/site-packages/portdatasplitter/main.py", line 55, in create_server
    self.serv.bind((ip, port))
OSError: [Errno 98] Address already in use

2021-05-04 06:36:25,281 - gravity_core.wlogger - ERROR - Traceback (most recent call last):
  File "/home/qodex/Gravity_core_export/gravity_core/wengine.py", line 76, in make_cps_connection
    self.cps.start()
  File "/home/qodex/.local/lib/python3.8/site-packages/portdatasplitter/main.py", line 36, in start
    self.create_server(self.server_ip, self.server_port)
  File "/home/qodex/.local/lib/python3.8/site-packages/portdatasplitter/main.py", line 55, in create_server
    self.serv.bind((ip, port))
OSError: [Errno 98] Address already in use

2021-05-04 06:36:30,287 - gravity_core.wlogger - ERROR - Traceback (most recent call last):
  File "/home/qodex/Gravity_core_export/gravity_core/wengine.py", line 76, in make_cps_connection
    self.cps.start()
  File "/home/qodex/.local/lib/python3.8/site-packages/portdatasplitter/main.py", line 36, in start
    self.create_server(self.server_ip, self.server_port)
  File "/home/qodex/.local/lib/python3.8/site-packages/portdatasplitter/main.py", line 55, in create_server
    self.serv.bind((ip, port))
OSError: [Errno 98] Address already in use

2021-05-04 06:36:35,294 - gravity_core.wlogger - ERROR - Traceback (most recent call last):
  File "/home/qodex/Gravity_core_export/gravity_core/wengine.py", line 76, in make_cps_connection
    self.cps.start()
  File "/home/qodex/.local/lib/python3.8/site-packages/portdatasplitter/main.py", line 36, in start
    self.create_server(self.server_ip, self.server_port)
  File "/home/qodex/.local/lib/python3.8/site-packages/portdatasplitter/main.py", line 55, in create_server
    self.serv.bind((ip, port))
OSError: [Errno 98] Address already in use

2021-05-04 06:36:40,302 - gravity_core.wlogger - ERROR - Traceback (most recent call last):
  File "/home/qodex/Gravity_core_export/gravity_core/wengine.py", line 76, in make_cps_connection
    self.cps.start()
  File "/home/qodex/.local/lib/python3.8/site-packages/portdatasplitter/main.py", line 36, in start
    self.create_server(self.server_ip, self.server_port)
  File "/home/qodex/.local/lib/python3.8/site-packages/portdatasplitter/main.py", line 55, in create_server
    self.serv.bind((ip, port))
OSError: [Errno 98] Address already in use

2021-05-04 06:36:45,309 - gravity_core.wlogger - ERROR - Traceback (most recent call last):
  File "/home/qodex/Gravity_core_export/gravity_core/wengine.py", line 76, in make_cps_connection
    self.cps.start()
  File "/home/qodex/.local/lib/python3.8/site-packages/portdatasplitter/main.py", line 36, in start
    self.create_server(self.server_ip, self.server_port)
  File "/home/qodex/.local/lib/python3.8/site-packages/portdatasplitter/main.py", line 55, in create_server
    self.serv.bind((ip, port))
OSError: [Errno 98] Address already in use

2021-05-04 06:36:45,311 - gravity_core.wlogger - ERROR - Traceback (most recent call last):
  File "/home/qodex/Gravity_core_export/gravity_core/wengine.py", line 76, in make_cps_connection
    self.cps.start()
  File "/home/qodex/.local/lib/python3.8/site-packages/portdatasplitter/main.py", line 36, in start
    self.create_server(self.server_ip, self.server_port)
  File "/home/qodex/.local/lib/python3.8/site-packages/portdatasplitter/main.py", line 55, in create_server
    self.serv.bind((ip, port))
OSError: [Errno 98] Address already in use

During handling of the above exception, another exception occurred:

Traceback (most recent call last):
  File "/home/qodex/Gravity_core_export/gravity_core/wlistener.py", line 102, in broadcastMsgSend
    conn.send(msg)
BrokenPipeError: [Errno 32] Broken pipe

2021-05-04 06:36:50,318 - gravity_core.wlogger - ERROR - Traceback (most recent call last):
  File "/home/qodex/Gravity_core_export/gravity_core/wengine.py", line 76, in make_cps_connection
    self.cps.start()
  File "/home/qodex/.local/lib/python3.8/site-packages/portdatasplitter/main.py", line 36, in start
    self.create_server(self.server_ip, self.server_port)
  File "/home/qodex/.local/lib/python3.8/site-packages/portdatasplitter/main.py", line 55, in create_server
    self.serv.bind((ip, port))
OSError: [Errno 98] Address already in use

2021-05-04 06:36:50,321 - gravity_core.wlogger - ERROR - Traceback (most recent call last):
  File "/home/qodex/Gravity_core_export/gravity_core/wengine.py", line 76, in make_cps_connection
    self.cps.start()
  File "/home/qodex/.local/lib/python3.8/site-packages/portdatasplitter/main.py", line 36, in start
    self.create_server(self.server_ip, self.server_port)
  File "/home/qodex/.local/lib/python3.8/site-packages/portdatasplitter/main.py", line 55, in create_server
    self.serv.bind((ip, port))
OSError: [Errno 98] Address already in use

During handling of the above exception, another exception occurred:

Traceback (most recent call last):
  File "/home/qodex/Gravity_core_export/gravity_core/wlistener.py", line 102, in broadcastMsgSend
    conn.send(msg)
BrokenPipeError: [Errno 32] Broken pipe

2021-05-04 06:36:55,327 - gravity_core.wlogger - ERROR - Traceback (most recent call last):
  File "/home/qodex/Gravity_core_export/gravity_core/wengine.py", line 76, in make_cps_connection
    self.cps.start()
  File "/home/qodex/.local/lib/python3.8/site-packages/portdatasplitter/main.py", line 36, in start
    self.create_server(self.server_ip, self.server_port)
  File "/home/qodex/.local/lib/python3.8/site-packages/portdatasplitter/main.py", line 55, in create_server
    self.serv.bind((ip, port))
OSError: [Errno 98] Address already in use

2021-05-04 06:36:55,329 - gravity_core.wlogger - ERROR - Traceback (most recent call last):
  File "/home/qodex/Gravity_core_export/gravity_core/wengine.py", line 76, in make_cps_connection
    self.cps.start()
  File "/home/qodex/.local/lib/python3.8/site-packages/portdatasplitter/main.py", line 36, in start
    self.create_server(self.server_ip, self.server_port)
  File "/home/qodex/.local/lib/python3.8/site-packages/portdatasplitter/main.py", line 55, in create_server
    self.serv.bind((ip, port))
OSError: [Errno 98] Address already in use

During handling of the above exception, another exception occurred:

Traceback (most recent call last):
  File "/home/qodex/Gravity_core_export/gravity_core/wlistener.py", line 102, in broadcastMsgSend
    conn.send(msg)
BrokenPipeError: [Errno 32] Broken pipe

2021-05-04 06:37:00,336 - gravity_core.wlogger - ERROR - Traceback (most recent call last):
  File "/home/qodex/Gravity_core_export/gravity_core/wengine.py", line 76, in make_cps_connection
    self.cps.start()
  File "/home/qodex/.local/lib/python3.8/site-packages/portdatasplitter/main.py", line 36, in start
    self.create_server(self.server_ip, self.server_port)
  File "/home/qodex/.local/lib/python3.8/site-packages/portdatasplitter/main.py", line 55, in create_server
    self.serv.bind((ip, port))
OSError: [Errno 98] Address already in use

2021-05-04 06:37:05,343 - gravity_core.wlogger - ERROR - Traceback (most recent call last):
  File "/home/qodex/Gravity_core_export/gravity_core/wengine.py", line 76, in make_cps_connection
    self.cps.start()
  File "/home/qodex/.local/lib/python3.8/site-packages/portdatasplitter/main.py", line 36, in start
    self.create_server(self.server_ip, self.server_port)
  File "/home/qodex/.local/lib/python3.8/site-packages/portdatasplitter/main.py", line 55, in create_server
    self.serv.bind((ip, port))
OSError: [Errno 98] Address already in use

2021-05-04 06:37:10,349 - gravity_core.wlogger - ERROR - Traceback (most recent call last):
  File "/home/qodex/Gravity_core_export/gravity_core/wengine.py", line 76, in make_cps_connection
    self.cps.start()
  File "/home/qodex/.local/lib/python3.8/site-packages/portdatasplitter/main.py", line 36, in start
    self.create_server(self.server_ip, self.server_port)
  File "/home/qodex/.local/lib/python3.8/site-packages/portdatasplitter/main.py", line 55, in create_server
    self.serv.bind((ip, port))
OSError: [Errno 98] Address already in use

2021-05-04 06:37:15,356 - gravity_core.wlogger - ERROR - Traceback (most recent call last):
  File "/home/qodex/Gravity_core_export/gravity_core/wengine.py", line 76, in make_cps_connection
    self.cps.start()
  File "/home/qodex/.local/lib/python3.8/site-packages/portdatasplitter/main.py", line 36, in start
    self.create_server(self.server_ip, self.server_port)
  File "/home/qodex/.local/lib/python3.8/site-packages/portdatasplitter/main.py", line 55, in create_server
    self.serv.bind((ip, port))
OSError: [Errno 98] Address already in use

2021-05-04 06:37:20,362 - gravity_core.wlogger - ERROR - Traceback (most recent call last):
  File "/home/qodex/Gravity_core_export/gravity_core/wengine.py", line 76, in make_cps_connection
    self.cps.start()
  File "/home/qodex/.local/lib/python3.8/site-packages/portdatasplitter/main.py", line 36, in start
    self.create_server(self.server_ip, self.server_port)
  File "/home/qodex/.local/lib/python3.8/site-packages/portdatasplitter/main.py", line 55, in create_server
    self.serv.bind((ip, port))
OSError: [Errno 98] Address already in use

2021-05-04 06:37:25,370 - gravity_core.wlogger - ERROR - Traceback (most recent call last):
  File "/home/qodex/Gravity_core_export/gravity_core/wengine.py", line 76, in make_cps_connection
    self.cps.start()
  File "/home/qodex/.local/lib/python3.8/site-packages/portdatasplitter/main.py", line 36, in start
    self.create_server(self.server_ip, self.server_port)
  File "/home/qodex/.local/lib/python3.8/site-packages/portdatasplitter/main.py", line 55, in create_server
    self.serv.bind((ip, port))
OSError: [Errno 98] Address already in use

2021-05-04 06:37:30,379 - gravity_core.wlogger - ERROR - Traceback (most recent call last):
  File "/home/qodex/Gravity_core_export/gravity_core/wengine.py", line 76, in make_cps_connection
    self.cps.start()
  File "/home/qodex/.local/lib/python3.8/site-packages/portdatasplitter/main.py", line 36, in start
    self.create_server(self.server_ip, self.server_port)
  File "/home/qodex/.local/lib/python3.8/site-packages/portdatasplitter/main.py", line 55, in create_server
    self.serv.bind((ip, port))
OSError: [Errno 98] Address already in use

2021-05-04 06:38:41,294 - gravity_core.wlogger - ERROR - Traceback (most recent call last):
  File "/home/qodex/Gravity_core_export/gravity_core/wlistener.py", line 102, in broadcastMsgSend
    conn.send(msg)
BrokenPipeError: [Errno 32] Broken pipe

2021-05-04 06:38:46,795 - gravity_core.wlogger - ERROR - Traceback (most recent call last):
  File "/home/qodex/Gravity_core_export/gravity_core/wlistener.py", line 102, in broadcastMsgSend
    conn.send(msg)
BrokenPipeError: [Errno 32] Broken pipe

2021-05-04 06:38:51,799 - gravity_core.wlogger - ERROR - Traceback (most recent call last):
  File "/home/qodex/Gravity_core_export/gravity_core/wlistener.py", line 102, in broadcastMsgSend
    conn.send(msg)
BrokenPipeError: [Errno 32] Broken pipe

2021-05-04 06:50:34,281 - gravity_core.wlogger - ERROR - Traceback (most recent call last):
  File "/home/qodex/Gravity_core_export/gravity_core/wlistener.py", line 102, in broadcastMsgSend
    conn.send(msg)
BrokenPipeError: [Errno 32] Broken pipe

2021-05-04 06:50:36,939 - gravity_core.wlogger - ERROR - Traceback (most recent call last):
  File "/home/qodex/Gravity_core_export/gravity_core/wlistener.py", line 102, in broadcastMsgSend
    conn.send(msg)
BrokenPipeError: [Errno 32] Broken pipe

2021-05-04 06:50:36,990 - gravity_core.wlogger - ERROR - Traceback (most recent call last):
  File "/home/qodex/Gravity_core_export/gravity_core/wlistener.py", line 102, in broadcastMsgSend
    conn.send(msg)
BrokenPipeError: [Errno 32] Broken pipe

2021-05-04 06:51:49,813 - gravity_core.wlogger - ERROR - Traceback (most recent call last):
  File "/home/qodex/Gravity_core_export/gravity_core/wengine.py", line 76, in make_cps_connection
    self.cps.start()
  File "/home/qodex/.local/lib/python3.8/site-packages/portdatasplitter/main.py", line 42, in start
    self._mainloop()
  File "/home/qodex/.local/lib/python3.8/site-packages/portdatasplitter/main.py", line 103, in _mainloop
    self.reconnect_logic()
  File "/home/qodex/.local/lib/python3.8/site-packages/portdatasplitter/main.py", line 118, in reconnect_logic
    self._mainloop()
  File "/home/qodex/.local/lib/python3.8/site-packages/portdatasplitter/main.py", line 96, in _mainloop
    data = self.port.readline()
  File "/home/qodex/.local/lib/python3.8/site-packages/serial/serialposix.py", line 595, in read
    raise SerialException(
serial.serialutil.SerialException: device reports readiness to read but returned no data (device disconnected or multiple access on port?)

2021-05-04 06:51:54,818 - gravity_core.wlogger - ERROR - Traceback (most recent call last):
  File "/home/qodex/Gravity_core_export/gravity_core/wengine.py", line 76, in make_cps_connection
    self.cps.start()
  File "/home/qodex/.local/lib/python3.8/site-packages/portdatasplitter/main.py", line 36, in start
    self.create_server(self.server_ip, self.server_port)
  File "/home/qodex/.local/lib/python3.8/site-packages/portdatasplitter/main.py", line 55, in create_server
    self.serv.bind((ip, port))
OSError: [Errno 98] Address already in use

2021-05-04 10:04:25,270 - gravity_core.wlogger - ERROR - Выход не зафиксирован фотоэлементом
2021-05-04 10:09:24,489 - gravity_core.wlogger - ERROR - Выход не зафиксирован фотоэлементом
2021-05-04 10:51:36,363 - gravity_core.wlogger - ERROR - Traceback (most recent call last):
  File "/home/qodex/Gravity_core_export/gravity_core/wengine.py", line 76, in make_cps_connection
    self.cps.start()
  File "/home/qodex/.local/lib/python3.8/site-packages/portdatasplitter/main.py", line 37, in start
    self.create_server(self.server_ip, self.server_port)
  File "/home/qodex/.local/lib/python3.8/site-packages/portdatasplitter/main.py", line 61, in create_server
    self.serv.bind((ip, port))
OSError: [Errno 98] Address already in use

2021-05-04 10:51:41,370 - gravity_core.wlogger - ERROR - Traceback (most recent call last):
  File "/home/qodex/Gravity_core_export/gravity_core/wengine.py", line 76, in make_cps_connection
    self.cps.start()
  File "/home/qodex/.local/lib/python3.8/site-packages/portdatasplitter/main.py", line 37, in start
    self.create_server(self.server_ip, self.server_port)
  File "/home/qodex/.local/lib/python3.8/site-packages/portdatasplitter/main.py", line 61, in create_server
    self.serv.bind((ip, port))
OSError: [Errno 98] Address already in use

2021-05-04 10:51:46,375 - gravity_core.wlogger - ERROR - Traceback (most recent call last):
  File "/home/qodex/Gravity_core_export/gravity_core/wengine.py", line 76, in make_cps_connection
    self.cps.start()
  File "/home/qodex/.local/lib/python3.8/site-packages/portdatasplitter/main.py", line 37, in start
    self.create_server(self.server_ip, self.server_port)
  File "/home/qodex/.local/lib/python3.8/site-packages/portdatasplitter/main.py", line 61, in create_server
    self.serv.bind((ip, port))
OSError: [Errno 98] Address already in use

2021-05-04 10:51:51,379 - gravity_core.wlogger - ERROR - Traceback (most recent call last):
  File "/home/qodex/Gravity_core_export/gravity_core/wengine.py", line 76, in make_cps_connection
    self.cps.start()
  File "/home/qodex/.local/lib/python3.8/site-packages/portdatasplitter/main.py", line 37, in start
    self.create_server(self.server_ip, self.server_port)
  File "/home/qodex/.local/lib/python3.8/site-packages/portdatasplitter/main.py", line 61, in create_server
    self.serv.bind((ip, port))
OSError: [Errno 98] Address already in use

2021-05-04 10:51:56,384 - gravity_core.wlogger - ERROR - Traceback (most recent call last):
  File "/home/qodex/Gravity_core_export/gravity_core/wengine.py", line 76, in make_cps_connection
    self.cps.start()
  File "/home/qodex/.local/lib/python3.8/site-packages/portdatasplitter/main.py", line 37, in start
    self.create_server(self.server_ip, self.server_port)
  File "/home/qodex/.local/lib/python3.8/site-packages/portdatasplitter/main.py", line 61, in create_server
    self.serv.bind((ip, port))
OSError: [Errno 98] Address already in use

2021-05-04 10:52:01,392 - gravity_core.wlogger - ERROR - Traceback (most recent call last):
  File "/home/qodex/Gravity_core_export/gravity_core/wengine.py", line 76, in make_cps_connection
    self.cps.start()
  File "/home/qodex/.local/lib/python3.8/site-packages/portdatasplitter/main.py", line 37, in start
    self.create_server(self.server_ip, self.server_port)
  File "/home/qodex/.local/lib/python3.8/site-packages/portdatasplitter/main.py", line 61, in create_server
    self.serv.bind((ip, port))
OSError: [Errno 98] Address already in use

2021-05-04 10:52:06,400 - gravity_core.wlogger - ERROR - Traceback (most recent call last):
  File "/home/qodex/Gravity_core_export/gravity_core/wengine.py", line 76, in make_cps_connection
    self.cps.start()
  File "/home/qodex/.local/lib/python3.8/site-packages/portdatasplitter/main.py", line 37, in start
    self.create_server(self.server_ip, self.server_port)
  File "/home/qodex/.local/lib/python3.8/site-packages/portdatasplitter/main.py", line 61, in create_server
    self.serv.bind((ip, port))
OSError: [Errno 98] Address already in use

2021-05-04 10:52:11,408 - gravity_core.wlogger - ERROR - Traceback (most recent call last):
  File "/home/qodex/Gravity_core_export/gravity_core/wengine.py", line 76, in make_cps_connection
    self.cps.start()
  File "/home/qodex/.local/lib/python3.8/site-packages/portdatasplitter/main.py", line 37, in start
    self.create_server(self.server_ip, self.server_port)
  File "/home/qodex/.local/lib/python3.8/site-packages/portdatasplitter/main.py", line 61, in create_server
    self.serv.bind((ip, port))
OSError: [Errno 98] Address already in use

2021-05-04 10:52:16,414 - gravity_core.wlogger - ERROR - Traceback (most recent call last):
  File "/home/qodex/Gravity_core_export/gravity_core/wengine.py", line 76, in make_cps_connection
    self.cps.start()
  File "/home/qodex/.local/lib/python3.8/site-packages/portdatasplitter/main.py", line 37, in start
    self.create_server(self.server_ip, self.server_port)
  File "/home/qodex/.local/lib/python3.8/site-packages/portdatasplitter/main.py", line 61, in create_server
    self.serv.bind((ip, port))
OSError: [Errno 98] Address already in use

2021-05-04 10:52:21,422 - gravity_core.wlogger - ERROR - Traceback (most recent call last):
  File "/home/qodex/Gravity_core_export/gravity_core/wengine.py", line 76, in make_cps_connection
    self.cps.start()
  File "/home/qodex/.local/lib/python3.8/site-packages/portdatasplitter/main.py", line 37, in start
    self.create_server(self.server_ip, self.server_port)
  File "/home/qodex/.local/lib/python3.8/site-packages/portdatasplitter/main.py", line 61, in create_server
    self.serv.bind((ip, port))
OSError: [Errno 98] Address already in use

2021-05-04 10:52:26,428 - gravity_core.wlogger - ERROR - Traceback (most recent call last):
  File "/home/qodex/Gravity_core_export/gravity_core/wengine.py", line 76, in make_cps_connection
    self.cps.start()
  File "/home/qodex/.local/lib/python3.8/site-packages/portdatasplitter/main.py", line 37, in start
    self.create_server(self.server_ip, self.server_port)
  File "/home/qodex/.local/lib/python3.8/site-packages/portdatasplitter/main.py", line 61, in create_server
    self.serv.bind((ip, port))
OSError: [Errno 98] Address already in use

2021-05-04 10:52:31,436 - gravity_core.wlogger - ERROR - Traceback (most recent call last):
  File "/home/qodex/Gravity_core_export/gravity_core/wengine.py", line 76, in make_cps_connection
    self.cps.start()
  File "/home/qodex/.local/lib/python3.8/site-packages/portdatasplitter/main.py", line 37, in start
    self.create_server(self.server_ip, self.server_port)
  File "/home/qodex/.local/lib/python3.8/site-packages/portdatasplitter/main.py", line 61, in create_server
    self.serv.bind((ip, port))
OSError: [Errno 98] Address already in use

2021-05-04 10:52:36,444 - gravity_core.wlogger - ERROR - Traceback (most recent call last):
  File "/home/qodex/Gravity_core_export/gravity_core/wengine.py", line 76, in make_cps_connection
    self.cps.start()
  File "/home/qodex/.local/lib/python3.8/site-packages/portdatasplitter/main.py", line 37, in start
    self.create_server(self.server_ip, self.server_port)
  File "/home/qodex/.local/lib/python3.8/site-packages/portdatasplitter/main.py", line 61, in create_server
    self.serv.bind((ip, port))
OSError: [Errno 98] Address already in use

2021-05-04 10:52:41,452 - gravity_core.wlogger - ERROR - Traceback (most recent call last):
  File "/home/qodex/Gravity_core_export/gravity_core/wengine.py", line 76, in make_cps_connection
    self.cps.start()
  File "/home/qodex/.local/lib/python3.8/site-packages/portdatasplitter/main.py", line 37, in start
    self.create_server(self.server_ip, self.server_port)
  File "/home/qodex/.local/lib/python3.8/site-packages/portdatasplitter/main.py", line 61, in create_server
    self.serv.bind((ip, port))
OSError: [Errno 98] Address already in use

2021-05-04 10:52:46,460 - gravity_core.wlogger - ERROR - Traceback (most recent call last):
  File "/home/qodex/Gravity_core_export/gravity_core/wengine.py", line 76, in make_cps_connection
    self.cps.start()
  File "/home/qodex/.local/lib/python3.8/site-packages/portdatasplitter/main.py", line 37, in start
    self.create_server(self.server_ip, self.server_port)
  File "/home/qodex/.local/lib/python3.8/site-packages/portdatasplitter/main.py", line 61, in create_server
    self.serv.bind((ip, port))
OSError: [Errno 98] Address already in use

2021-05-04 10:52:51,468 - gravity_core.wlogger - ERROR - Traceback (most recent call last):
  File "/home/qodex/Gravity_core_export/gravity_core/wengine.py", line 76, in make_cps_connection
    self.cps.start()
  File "/home/qodex/.local/lib/python3.8/site-packages/portdatasplitter/main.py", line 37, in start
    self.create_server(self.server_ip, self.server_port)
  File "/home/qodex/.local/lib/python3.8/site-packages/portdatasplitter/main.py", line 61, in create_server
    self.serv.bind((ip, port))
OSError: [Errno 98] Address already in use

2021-05-04 10:52:56,477 - gravity_core.wlogger - ERROR - Traceback (most recent call last):
  File "/home/qodex/Gravity_core_export/gravity_core/wengine.py", line 76, in make_cps_connection
    self.cps.start()
  File "/home/qodex/.local/lib/python3.8/site-packages/portdatasplitter/main.py", line 37, in start
    self.create_server(self.server_ip, self.server_port)
  File "/home/qodex/.local/lib/python3.8/site-packages/portdatasplitter/main.py", line 61, in create_server
    self.serv.bind((ip, port))
OSError: [Errno 98] Address already in use

2021-05-04 10:53:01,484 - gravity_core.wlogger - ERROR - Traceback (most recent call last):
  File "/home/qodex/Gravity_core_export/gravity_core/wengine.py", line 76, in make_cps_connection
    self.cps.start()
  File "/home/qodex/.local/lib/python3.8/site-packages/portdatasplitter/main.py", line 37, in start
    self.create_server(self.server_ip, self.server_port)
  File "/home/qodex/.local/lib/python3.8/site-packages/portdatasplitter/main.py", line 61, in create_server
    self.serv.bind((ip, port))
OSError: [Errno 98] Address already in use

2021-05-04 10:53:06,492 - gravity_core.wlogger - ERROR - Traceback (most recent call last):
  File "/home/qodex/Gravity_core_export/gravity_core/wengine.py", line 76, in make_cps_connection
    self.cps.start()
  File "/home/qodex/.local/lib/python3.8/site-packages/portdatasplitter/main.py", line 37, in start
    self.create_server(self.server_ip, self.server_port)
  File "/home/qodex/.local/lib/python3.8/site-packages/portdatasplitter/main.py", line 61, in create_server
    self.serv.bind((ip, port))
OSError: [Errno 98] Address already in use

2021-05-04 10:53:11,500 - gravity_core.wlogger - ERROR - Traceback (most recent call last):
  File "/home/qodex/Gravity_core_export/gravity_core/wengine.py", line 76, in make_cps_connection
    self.cps.start()
  File "/home/qodex/.local/lib/python3.8/site-packages/portdatasplitter/main.py", line 37, in start
    self.create_server(self.server_ip, self.server_port)
  File "/home/qodex/.local/lib/python3.8/site-packages/portdatasplitter/main.py", line 61, in create_server
    self.serv.bind((ip, port))
OSError: [Errno 98] Address already in use

2021-05-04 10:53:16,508 - gravity_core.wlogger - ERROR - Traceback (most recent call last):
  File "/home/qodex/Gravity_core_export/gravity_core/wengine.py", line 76, in make_cps_connection
    self.cps.start()
  File "/home/qodex/.local/lib/python3.8/site-packages/portdatasplitter/main.py", line 37, in start
    self.create_server(self.server_ip, self.server_port)
  File "/home/qodex/.local/lib/python3.8/site-packages/portdatasplitter/main.py", line 61, in create_server
    self.serv.bind((ip, port))
OSError: [Errno 98] Address already in use

2021-05-04 10:53:21,516 - gravity_core.wlogger - ERROR - Traceback (most recent call last):
  File "/home/qodex/Gravity_core_export/gravity_core/wengine.py", line 76, in make_cps_connection
    self.cps.start()
  File "/home/qodex/.local/lib/python3.8/site-packages/portdatasplitter/main.py", line 37, in start
    self.create_server(self.server_ip, self.server_port)
  File "/home/qodex/.local/lib/python3.8/site-packages/portdatasplitter/main.py", line 61, in create_server
    self.serv.bind((ip, port))
OSError: [Errno 98] Address already in use

2021-05-04 10:53:26,524 - gravity_core.wlogger - ERROR - Traceback (most recent call last):
  File "/home/qodex/Gravity_core_export/gravity_core/wengine.py", line 76, in make_cps_connection
    self.cps.start()
  File "/home/qodex/.local/lib/python3.8/site-packages/portdatasplitter/main.py", line 37, in start
    self.create_server(self.server_ip, self.server_port)
  File "/home/qodex/.local/lib/python3.8/site-packages/portdatasplitter/main.py", line 61, in create_server
    self.serv.bind((ip, port))
OSError: [Errno 98] Address already in use

2021-05-04 10:53:31,530 - gravity_core.wlogger - ERROR - Traceback (most recent call last):
  File "/home/qodex/Gravity_core_export/gravity_core/wengine.py", line 76, in make_cps_connection
    self.cps.start()
  File "/home/qodex/.local/lib/python3.8/site-packages/portdatasplitter/main.py", line 37, in start
    self.create_server(self.server_ip, self.server_port)
  File "/home/qodex/.local/lib/python3.8/site-packages/portdatasplitter/main.py", line 61, in create_server
    self.serv.bind((ip, port))
OSError: [Errno 98] Address already in use

2021-05-04 10:53:36,538 - gravity_core.wlogger - ERROR - Traceback (most recent call last):
  File "/home/qodex/Gravity_core_export/gravity_core/wengine.py", line 76, in make_cps_connection
    self.cps.start()
  File "/home/qodex/.local/lib/python3.8/site-packages/portdatasplitter/main.py", line 37, in start
    self.create_server(self.server_ip, self.server_port)
  File "/home/qodex/.local/lib/python3.8/site-packages/portdatasplitter/main.py", line 61, in create_server
    self.serv.bind((ip, port))
OSError: [Errno 98] Address already in use

2021-05-04 10:53:41,544 - gravity_core.wlogger - ERROR - Traceback (most recent call last):
  File "/home/qodex/Gravity_core_export/gravity_core/wengine.py", line 76, in make_cps_connection
    self.cps.start()
  File "/home/qodex/.local/lib/python3.8/site-packages/portdatasplitter/main.py", line 37, in start
    self.create_server(self.server_ip, self.server_port)
  File "/home/qodex/.local/lib/python3.8/site-packages/portdatasplitter/main.py", line 61, in create_server
    self.serv.bind((ip, port))
OSError: [Errno 98] Address already in use

2021-05-04 10:53:46,552 - gravity_core.wlogger - ERROR - Traceback (most recent call last):
  File "/home/qodex/Gravity_core_export/gravity_core/wengine.py", line 76, in make_cps_connection
    self.cps.start()
  File "/home/qodex/.local/lib/python3.8/site-packages/portdatasplitter/main.py", line 37, in start
    self.create_server(self.server_ip, self.server_port)
  File "/home/qodex/.local/lib/python3.8/site-packages/portdatasplitter/main.py", line 61, in create_server
    self.serv.bind((ip, port))
OSError: [Errno 98] Address already in use

2021-05-04 10:53:51,561 - gravity_core.wlogger - ERROR - Traceback (most recent call last):
  File "/home/qodex/Gravity_core_export/gravity_core/wengine.py", line 76, in make_cps_connection
    self.cps.start()
  File "/home/qodex/.local/lib/python3.8/site-packages/portdatasplitter/main.py", line 37, in start
    self.create_server(self.server_ip, self.server_port)
  File "/home/qodex/.local/lib/python3.8/site-packages/portdatasplitter/main.py", line 61, in create_server
    self.serv.bind((ip, port))
OSError: [Errno 98] Address already in use

2021-05-04 10:53:56,569 - gravity_core.wlogger - ERROR - Traceback (most recent call last):
  File "/home/qodex/Gravity_core_export/gravity_core/wengine.py", line 76, in make_cps_connection
    self.cps.start()
  File "/home/qodex/.local/lib/python3.8/site-packages/portdatasplitter/main.py", line 37, in start
    self.create_server(self.server_ip, self.server_port)
  File "/home/qodex/.local/lib/python3.8/site-packages/portdatasplitter/main.py", line 61, in create_server
    self.serv.bind((ip, port))
OSError: [Errno 98] Address already in use

2021-05-04 10:54:01,578 - gravity_core.wlogger - ERROR - Traceback (most recent call last):
  File "/home/qodex/Gravity_core_export/gravity_core/wengine.py", line 76, in make_cps_connection
    self.cps.start()
  File "/home/qodex/.local/lib/python3.8/site-packages/portdatasplitter/main.py", line 37, in start
    self.create_server(self.server_ip, self.server_port)
  File "/home/qodex/.local/lib/python3.8/site-packages/portdatasplitter/main.py", line 61, in create_server
    self.serv.bind((ip, port))
OSError: [Errno 98] Address already in use

2021-05-04 10:54:06,583 - gravity_core.wlogger - ERROR - Traceback (most recent call last):
  File "/home/qodex/Gravity_core_export/gravity_core/wengine.py", line 76, in make_cps_connection
    self.cps.start()
  File "/home/qodex/.local/lib/python3.8/site-packages/portdatasplitter/main.py", line 37, in start
    self.create_server(self.server_ip, self.server_port)
  File "/home/qodex/.local/lib/python3.8/site-packages/portdatasplitter/main.py", line 61, in create_server
    self.serv.bind((ip, port))
OSError: [Errno 98] Address already in use

2021-05-04 10:54:11,591 - gravity_core.wlogger - ERROR - Traceback (most recent call last):
  File "/home/qodex/Gravity_core_export/gravity_core/wengine.py", line 76, in make_cps_connection
    self.cps.start()
  File "/home/qodex/.local/lib/python3.8/site-packages/portdatasplitter/main.py", line 37, in start
    self.create_server(self.server_ip, self.server_port)
  File "/home/qodex/.local/lib/python3.8/site-packages/portdatasplitter/main.py", line 61, in create_server
    self.serv.bind((ip, port))
OSError: [Errno 98] Address already in use

2021-05-04 10:54:16,599 - gravity_core.wlogger - ERROR - Traceback (most recent call last):
  File "/home/qodex/Gravity_core_export/gravity_core/wengine.py", line 76, in make_cps_connection
    self.cps.start()
  File "/home/qodex/.local/lib/python3.8/site-packages/portdatasplitter/main.py", line 37, in start
    self.create_server(self.server_ip, self.server_port)
  File "/home/qodex/.local/lib/python3.8/site-packages/portdatasplitter/main.py", line 61, in create_server
    self.serv.bind((ip, port))
OSError: [Errno 98] Address already in use

2021-05-04 10:54:21,607 - gravity_core.wlogger - ERROR - Traceback (most recent call last):
  File "/home/qodex/Gravity_core_export/gravity_core/wengine.py", line 76, in make_cps_connection
    self.cps.start()
  File "/home/qodex/.local/lib/python3.8/site-packages/portdatasplitter/main.py", line 37, in start
    self.create_server(self.server_ip, self.server_port)
  File "/home/qodex/.local/lib/python3.8/site-packages/portdatasplitter/main.py", line 61, in create_server
    self.serv.bind((ip, port))
OSError: [Errno 98] Address already in use

2021-05-04 10:54:26,615 - gravity_core.wlogger - ERROR - Traceback (most recent call last):
  File "/home/qodex/Gravity_core_export/gravity_core/wengine.py", line 76, in make_cps_connection
    self.cps.start()
  File "/home/qodex/.local/lib/python3.8/site-packages/portdatasplitter/main.py", line 37, in start
    self.create_server(self.server_ip, self.server_port)
  File "/home/qodex/.local/lib/python3.8/site-packages/portdatasplitter/main.py", line 61, in create_server
    self.serv.bind((ip, port))
OSError: [Errno 98] Address already in use

2021-05-04 10:54:31,620 - gravity_core.wlogger - ERROR - Traceback (most recent call last):
  File "/home/qodex/Gravity_core_export/gravity_core/wengine.py", line 76, in make_cps_connection
    self.cps.start()
  File "/home/qodex/.local/lib/python3.8/site-packages/portdatasplitter/main.py", line 37, in start
    self.create_server(self.server_ip, self.server_port)
  File "/home/qodex/.local/lib/python3.8/site-packages/portdatasplitter/main.py", line 61, in create_server
    self.serv.bind((ip, port))
OSError: [Errno 98] Address already in use

2021-05-04 10:54:36,628 - gravity_core.wlogger - ERROR - Traceback (most recent call last):
  File "/home/qodex/Gravity_core_export/gravity_core/wengine.py", line 76, in make_cps_connection
    self.cps.start()
  File "/home/qodex/.local/lib/python3.8/site-packages/portdatasplitter/main.py", line 37, in start
    self.create_server(self.server_ip, self.server_port)
  File "/home/qodex/.local/lib/python3.8/site-packages/portdatasplitter/main.py", line 61, in create_server
    self.serv.bind((ip, port))
OSError: [Errno 98] Address already in use

2021-05-04 10:54:41,636 - gravity_core.wlogger - ERROR - Traceback (most recent call last):
  File "/home/qodex/Gravity_core_export/gravity_core/wengine.py", line 76, in make_cps_connection
    self.cps.start()
  File "/home/qodex/.local/lib/python3.8/site-packages/portdatasplitter/main.py", line 37, in start
    self.create_server(self.server_ip, self.server_port)
  File "/home/qodex/.local/lib/python3.8/site-packages/portdatasplitter/main.py", line 61, in create_server
    self.serv.bind((ip, port))
OSError: [Errno 98] Address already in use

2021-05-04 10:54:46,644 - gravity_core.wlogger - ERROR - Traceback (most recent call last):
  File "/home/qodex/Gravity_core_export/gravity_core/wengine.py", line 76, in make_cps_connection
    self.cps.start()
  File "/home/qodex/.local/lib/python3.8/site-packages/portdatasplitter/main.py", line 37, in start
    self.create_server(self.server_ip, self.server_port)
  File "/home/qodex/.local/lib/python3.8/site-packages/portdatasplitter/main.py", line 61, in create_server
    self.serv.bind((ip, port))
OSError: [Errno 98] Address already in use

2021-05-04 10:54:51,652 - gravity_core.wlogger - ERROR - Traceback (most recent call last):
  File "/home/qodex/Gravity_core_export/gravity_core/wengine.py", line 76, in make_cps_connection
    self.cps.start()
  File "/home/qodex/.local/lib/python3.8/site-packages/portdatasplitter/main.py", line 37, in start
    self.create_server(self.server_ip, self.server_port)
  File "/home/qodex/.local/lib/python3.8/site-packages/portdatasplitter/main.py", line 61, in create_server
    self.serv.bind((ip, port))
OSError: [Errno 98] Address already in use

2021-05-04 10:54:56,660 - gravity_core.wlogger - ERROR - Traceback (most recent call last):
  File "/home/qodex/Gravity_core_export/gravity_core/wengine.py", line 76, in make_cps_connection
    self.cps.start()
  File "/home/qodex/.local/lib/python3.8/site-packages/portdatasplitter/main.py", line 37, in start
    self.create_server(self.server_ip, self.server_port)
  File "/home/qodex/.local/lib/python3.8/site-packages/portdatasplitter/main.py", line 61, in create_server
    self.serv.bind((ip, port))
OSError: [Errno 98] Address already in use

2021-05-04 10:55:01,668 - gravity_core.wlogger - ERROR - Traceback (most recent call last):
  File "/home/qodex/Gravity_core_export/gravity_core/wengine.py", line 76, in make_cps_connection
    self.cps.start()
  File "/home/qodex/.local/lib/python3.8/site-packages/portdatasplitter/main.py", line 37, in start
    self.create_server(self.server_ip, self.server_port)
  File "/home/qodex/.local/lib/python3.8/site-packages/portdatasplitter/main.py", line 61, in create_server
    self.serv.bind((ip, port))
OSError: [Errno 98] Address already in use

2021-05-04 10:55:06,671 - gravity_core.wlogger - ERROR - Traceback (most recent call last):
  File "/home/qodex/Gravity_core_export/gravity_core/wengine.py", line 76, in make_cps_connection
    self.cps.start()
  File "/home/qodex/.local/lib/python3.8/site-packages/portdatasplitter/main.py", line 37, in start
    self.create_server(self.server_ip, self.server_port)
  File "/home/qodex/.local/lib/python3.8/site-packages/portdatasplitter/main.py", line 61, in create_server
    self.serv.bind((ip, port))
OSError: [Errno 98] Address already in use

2021-05-04 10:55:11,675 - gravity_core.wlogger - ERROR - Traceback (most recent call last):
  File "/home/qodex/Gravity_core_export/gravity_core/wengine.py", line 76, in make_cps_connection
    self.cps.start()
  File "/home/qodex/.local/lib/python3.8/site-packages/portdatasplitter/main.py", line 37, in start
    self.create_server(self.server_ip, self.server_port)
  File "/home/qodex/.local/lib/python3.8/site-packages/portdatasplitter/main.py", line 61, in create_server
    self.serv.bind((ip, port))
OSError: [Errno 98] Address already in use

2021-05-04 10:55:16,680 - gravity_core.wlogger - ERROR - Traceback (most recent call last):
  File "/home/qodex/Gravity_core_export/gravity_core/wengine.py", line 76, in make_cps_connection
    self.cps.start()
  File "/home/qodex/.local/lib/python3.8/site-packages/portdatasplitter/main.py", line 37, in start
    self.create_server(self.server_ip, self.server_port)
  File "/home/qodex/.local/lib/python3.8/site-packages/portdatasplitter/main.py", line 61, in create_server
    self.serv.bind((ip, port))
OSError: [Errno 98] Address already in use

2021-05-04 10:55:21,688 - gravity_core.wlogger - ERROR - Traceback (most recent call last):
  File "/home/qodex/Gravity_core_export/gravity_core/wengine.py", line 76, in make_cps_connection
    self.cps.start()
  File "/home/qodex/.local/lib/python3.8/site-packages/portdatasplitter/main.py", line 37, in start
    self.create_server(self.server_ip, self.server_port)
  File "/home/qodex/.local/lib/python3.8/site-packages/portdatasplitter/main.py", line 61, in create_server
    self.serv.bind((ip, port))
OSError: [Errno 98] Address already in use

2021-05-04 10:55:26,697 - gravity_core.wlogger - ERROR - Traceback (most recent call last):
  File "/home/qodex/Gravity_core_export/gravity_core/wengine.py", line 76, in make_cps_connection
    self.cps.start()
  File "/home/qodex/.local/lib/python3.8/site-packages/portdatasplitter/main.py", line 37, in start
    self.create_server(self.server_ip, self.server_port)
  File "/home/qodex/.local/lib/python3.8/site-packages/portdatasplitter/main.py", line 61, in create_server
    self.serv.bind((ip, port))
OSError: [Errno 98] Address already in use

2021-05-04 10:55:31,704 - gravity_core.wlogger - ERROR - Traceback (most recent call last):
  File "/home/qodex/Gravity_core_export/gravity_core/wengine.py", line 76, in make_cps_connection
    self.cps.start()
  File "/home/qodex/.local/lib/python3.8/site-packages/portdatasplitter/main.py", line 37, in start
    self.create_server(self.server_ip, self.server_port)
  File "/home/qodex/.local/lib/python3.8/site-packages/portdatasplitter/main.py", line 61, in create_server
    self.serv.bind((ip, port))
OSError: [Errno 98] Address already in use

2021-05-04 10:55:36,711 - gravity_core.wlogger - ERROR - Traceback (most recent call last):
  File "/home/qodex/Gravity_core_export/gravity_core/wengine.py", line 76, in make_cps_connection
    self.cps.start()
  File "/home/qodex/.local/lib/python3.8/site-packages/portdatasplitter/main.py", line 37, in start
    self.create_server(self.server_ip, self.server_port)
  File "/home/qodex/.local/lib/python3.8/site-packages/portdatasplitter/main.py", line 61, in create_server
    self.serv.bind((ip, port))
OSError: [Errno 98] Address already in use

2021-05-04 10:55:41,716 - gravity_core.wlogger - ERROR - Traceback (most recent call last):
  File "/home/qodex/Gravity_core_export/gravity_core/wengine.py", line 76, in make_cps_connection
    self.cps.start()
  File "/home/qodex/.local/lib/python3.8/site-packages/portdatasplitter/main.py", line 37, in start
    self.create_server(self.server_ip, self.server_port)
  File "/home/qodex/.local/lib/python3.8/site-packages/portdatasplitter/main.py", line 61, in create_server
    self.serv.bind((ip, port))
OSError: [Errno 98] Address already in use

2021-05-04 10:55:46,723 - gravity_core.wlogger - ERROR - Traceback (most recent call last):
  File "/home/qodex/Gravity_core_export/gravity_core/wengine.py", line 76, in make_cps_connection
    self.cps.start()
  File "/home/qodex/.local/lib/python3.8/site-packages/portdatasplitter/main.py", line 37, in start
    self.create_server(self.server_ip, self.server_port)
  File "/home/qodex/.local/lib/python3.8/site-packages/portdatasplitter/main.py", line 61, in create_server
    self.serv.bind((ip, port))
OSError: [Errno 98] Address already in use

2021-05-04 10:55:51,731 - gravity_core.wlogger - ERROR - Traceback (most recent call last):
  File "/home/qodex/Gravity_core_export/gravity_core/wengine.py", line 76, in make_cps_connection
    self.cps.start()
  File "/home/qodex/.local/lib/python3.8/site-packages/portdatasplitter/main.py", line 37, in start
    self.create_server(self.server_ip, self.server_port)
  File "/home/qodex/.local/lib/python3.8/site-packages/portdatasplitter/main.py", line 61, in create_server
    self.serv.bind((ip, port))
OSError: [Errno 98] Address already in use

2021-05-04 10:55:56,736 - gravity_core.wlogger - ERROR - Traceback (most recent call last):
  File "/home/qodex/Gravity_core_export/gravity_core/wengine.py", line 76, in make_cps_connection
    self.cps.start()
  File "/home/qodex/.local/lib/python3.8/site-packages/portdatasplitter/main.py", line 37, in start
    self.create_server(self.server_ip, self.server_port)
  File "/home/qodex/.local/lib/python3.8/site-packages/portdatasplitter/main.py", line 61, in create_server
    self.serv.bind((ip, port))
OSError: [Errno 98] Address already in use

2021-05-04 10:56:01,744 - gravity_core.wlogger - ERROR - Traceback (most recent call last):
  File "/home/qodex/Gravity_core_export/gravity_core/wengine.py", line 76, in make_cps_connection
    self.cps.start()
  File "/home/qodex/.local/lib/python3.8/site-packages/portdatasplitter/main.py", line 37, in start
    self.create_server(self.server_ip, self.server_port)
  File "/home/qodex/.local/lib/python3.8/site-packages/portdatasplitter/main.py", line 61, in create_server
    self.serv.bind((ip, port))
OSError: [Errno 98] Address already in use

2021-05-04 10:56:06,752 - gravity_core.wlogger - ERROR - Traceback (most recent call last):
  File "/home/qodex/Gravity_core_export/gravity_core/wengine.py", line 76, in make_cps_connection
    self.cps.start()
  File "/home/qodex/.local/lib/python3.8/site-packages/portdatasplitter/main.py", line 37, in start
    self.create_server(self.server_ip, self.server_port)
  File "/home/qodex/.local/lib/python3.8/site-packages/portdatasplitter/main.py", line 61, in create_server
    self.serv.bind((ip, port))
OSError: [Errno 98] Address already in use

2021-05-04 10:56:11,760 - gravity_core.wlogger - ERROR - Traceback (most recent call last):
  File "/home/qodex/Gravity_core_export/gravity_core/wengine.py", line 76, in make_cps_connection
    self.cps.start()
  File "/home/qodex/.local/lib/python3.8/site-packages/portdatasplitter/main.py", line 37, in start
    self.create_server(self.server_ip, self.server_port)
  File "/home/qodex/.local/lib/python3.8/site-packages/portdatasplitter/main.py", line 61, in create_server
    self.serv.bind((ip, port))
OSError: [Errno 98] Address already in use

2021-05-04 10:56:16,769 - gravity_core.wlogger - ERROR - Traceback (most recent call last):
  File "/home/qodex/Gravity_core_export/gravity_core/wengine.py", line 76, in make_cps_connection
    self.cps.start()
  File "/home/qodex/.local/lib/python3.8/site-packages/portdatasplitter/main.py", line 37, in start
    self.create_server(self.server_ip, self.server_port)
  File "/home/qodex/.local/lib/python3.8/site-packages/portdatasplitter/main.py", line 61, in create_server
    self.serv.bind((ip, port))
OSError: [Errno 98] Address already in use

2021-05-04 10:56:21,777 - gravity_core.wlogger - ERROR - Traceback (most recent call last):
  File "/home/qodex/Gravity_core_export/gravity_core/wengine.py", line 76, in make_cps_connection
    self.cps.start()
  File "/home/qodex/.local/lib/python3.8/site-packages/portdatasplitter/main.py", line 37, in start
    self.create_server(self.server_ip, self.server_port)
  File "/home/qodex/.local/lib/python3.8/site-packages/portdatasplitter/main.py", line 61, in create_server
    self.serv.bind((ip, port))
OSError: [Errno 98] Address already in use

2021-05-04 10:56:26,783 - gravity_core.wlogger - ERROR - Traceback (most recent call last):
  File "/home/qodex/Gravity_core_export/gravity_core/wengine.py", line 76, in make_cps_connection
    self.cps.start()
  File "/home/qodex/.local/lib/python3.8/site-packages/portdatasplitter/main.py", line 37, in start
    self.create_server(self.server_ip, self.server_port)
  File "/home/qodex/.local/lib/python3.8/site-packages/portdatasplitter/main.py", line 61, in create_server
    self.serv.bind((ip, port))
OSError: [Errno 98] Address already in use

2021-05-04 10:56:31,788 - gravity_core.wlogger - ERROR - Traceback (most recent call last):
  File "/home/qodex/Gravity_core_export/gravity_core/wengine.py", line 76, in make_cps_connection
    self.cps.start()
  File "/home/qodex/.local/lib/python3.8/site-packages/portdatasplitter/main.py", line 37, in start
    self.create_server(self.server_ip, self.server_port)
  File "/home/qodex/.local/lib/python3.8/site-packages/portdatasplitter/main.py", line 61, in create_server
    self.serv.bind((ip, port))
OSError: [Errno 98] Address already in use

2021-05-04 10:56:36,796 - gravity_core.wlogger - ERROR - Traceback (most recent call last):
  File "/home/qodex/Gravity_core_export/gravity_core/wengine.py", line 76, in make_cps_connection
    self.cps.start()
  File "/home/qodex/.local/lib/python3.8/site-packages/portdatasplitter/main.py", line 37, in start
    self.create_server(self.server_ip, self.server_port)
  File "/home/qodex/.local/lib/python3.8/site-packages/portdatasplitter/main.py", line 61, in create_server
    self.serv.bind((ip, port))
OSError: [Errno 98] Address already in use

2021-05-04 10:56:41,803 - gravity_core.wlogger - ERROR - Traceback (most recent call last):
  File "/home/qodex/Gravity_core_export/gravity_core/wengine.py", line 76, in make_cps_connection
    self.cps.start()
  File "/home/qodex/.local/lib/python3.8/site-packages/portdatasplitter/main.py", line 37, in start
    self.create_server(self.server_ip, self.server_port)
  File "/home/qodex/.local/lib/python3.8/site-packages/portdatasplitter/main.py", line 61, in create_server
    self.serv.bind((ip, port))
OSError: [Errno 98] Address already in use

2021-05-04 10:56:46,807 - gravity_core.wlogger - ERROR - Traceback (most recent call last):
  File "/home/qodex/Gravity_core_export/gravity_core/wengine.py", line 76, in make_cps_connection
    self.cps.start()
  File "/home/qodex/.local/lib/python3.8/site-packages/portdatasplitter/main.py", line 37, in start
    self.create_server(self.server_ip, self.server_port)
  File "/home/qodex/.local/lib/python3.8/site-packages/portdatasplitter/main.py", line 61, in create_server
    self.serv.bind((ip, port))
OSError: [Errno 98] Address already in use

2021-05-04 10:56:51,810 - gravity_core.wlogger - ERROR - Traceback (most recent call last):
  File "/home/qodex/Gravity_core_export/gravity_core/wengine.py", line 76, in make_cps_connection
    self.cps.start()
  File "/home/qodex/.local/lib/python3.8/site-packages/portdatasplitter/main.py", line 37, in start
    self.create_server(self.server_ip, self.server_port)
  File "/home/qodex/.local/lib/python3.8/site-packages/portdatasplitter/main.py", line 61, in create_server
    self.serv.bind((ip, port))
OSError: [Errno 98] Address already in use

2021-05-04 10:56:56,816 - gravity_core.wlogger - ERROR - Traceback (most recent call last):
  File "/home/qodex/Gravity_core_export/gravity_core/wengine.py", line 76, in make_cps_connection
    self.cps.start()
  File "/home/qodex/.local/lib/python3.8/site-packages/portdatasplitter/main.py", line 37, in start
    self.create_server(self.server_ip, self.server_port)
  File "/home/qodex/.local/lib/python3.8/site-packages/portdatasplitter/main.py", line 61, in create_server
    self.serv.bind((ip, port))
OSError: [Errno 98] Address already in use

2021-05-04 10:57:01,824 - gravity_core.wlogger - ERROR - Traceback (most recent call last):
  File "/home/qodex/Gravity_core_export/gravity_core/wengine.py", line 76, in make_cps_connection
    self.cps.start()
  File "/home/qodex/.local/lib/python3.8/site-packages/portdatasplitter/main.py", line 37, in start
    self.create_server(self.server_ip, self.server_port)
  File "/home/qodex/.local/lib/python3.8/site-packages/portdatasplitter/main.py", line 61, in create_server
    self.serv.bind((ip, port))
OSError: [Errno 98] Address already in use

2021-05-04 10:57:06,828 - gravity_core.wlogger - ERROR - Traceback (most recent call last):
  File "/home/qodex/Gravity_core_export/gravity_core/wengine.py", line 76, in make_cps_connection
    self.cps.start()
  File "/home/qodex/.local/lib/python3.8/site-packages/portdatasplitter/main.py", line 37, in start
    self.create_server(self.server_ip, self.server_port)
  File "/home/qodex/.local/lib/python3.8/site-packages/portdatasplitter/main.py", line 61, in create_server
    self.serv.bind((ip, port))
OSError: [Errno 98] Address already in use

2021-05-04 10:57:11,836 - gravity_core.wlogger - ERROR - Traceback (most recent call last):
  File "/home/qodex/Gravity_core_export/gravity_core/wengine.py", line 76, in make_cps_connection
    self.cps.start()
  File "/home/qodex/.local/lib/python3.8/site-packages/portdatasplitter/main.py", line 37, in start
    self.create_server(self.server_ip, self.server_port)
  File "/home/qodex/.local/lib/python3.8/site-packages/portdatasplitter/main.py", line 61, in create_server
    self.serv.bind((ip, port))
OSError: [Errno 98] Address already in use

2021-05-04 10:57:16,844 - gravity_core.wlogger - ERROR - Traceback (most recent call last):
  File "/home/qodex/Gravity_core_export/gravity_core/wengine.py", line 76, in make_cps_connection
    self.cps.start()
  File "/home/qodex/.local/lib/python3.8/site-packages/portdatasplitter/main.py", line 37, in start
    self.create_server(self.server_ip, self.server_port)
  File "/home/qodex/.local/lib/python3.8/site-packages/portdatasplitter/main.py", line 61, in create_server
    self.serv.bind((ip, port))
OSError: [Errno 98] Address already in use

2021-05-04 10:57:21,853 - gravity_core.wlogger - ERROR - Traceback (most recent call last):
  File "/home/qodex/Gravity_core_export/gravity_core/wengine.py", line 76, in make_cps_connection
    self.cps.start()
  File "/home/qodex/.local/lib/python3.8/site-packages/portdatasplitter/main.py", line 37, in start
    self.create_server(self.server_ip, self.server_port)
  File "/home/qodex/.local/lib/python3.8/site-packages/portdatasplitter/main.py", line 61, in create_server
    self.serv.bind((ip, port))
OSError: [Errno 98] Address already in use

2021-05-04 10:57:26,859 - gravity_core.wlogger - ERROR - Traceback (most recent call last):
  File "/home/qodex/Gravity_core_export/gravity_core/wengine.py", line 76, in make_cps_connection
    self.cps.start()
  File "/home/qodex/.local/lib/python3.8/site-packages/portdatasplitter/main.py", line 37, in start
    self.create_server(self.server_ip, self.server_port)
  File "/home/qodex/.local/lib/python3.8/site-packages/portdatasplitter/main.py", line 61, in create_server
    self.serv.bind((ip, port))
OSError: [Errno 98] Address already in use

2021-05-04 10:57:31,867 - gravity_core.wlogger - ERROR - Traceback (most recent call last):
  File "/home/qodex/Gravity_core_export/gravity_core/wengine.py", line 76, in make_cps_connection
    self.cps.start()
  File "/home/qodex/.local/lib/python3.8/site-packages/portdatasplitter/main.py", line 37, in start
    self.create_server(self.server_ip, self.server_port)
  File "/home/qodex/.local/lib/python3.8/site-packages/portdatasplitter/main.py", line 61, in create_server
    self.serv.bind((ip, port))
OSError: [Errno 98] Address already in use

2021-05-04 10:57:36,872 - gravity_core.wlogger - ERROR - Traceback (most recent call last):
  File "/home/qodex/Gravity_core_export/gravity_core/wengine.py", line 76, in make_cps_connection
    self.cps.start()
  File "/home/qodex/.local/lib/python3.8/site-packages/portdatasplitter/main.py", line 37, in start
    self.create_server(self.server_ip, self.server_port)
  File "/home/qodex/.local/lib/python3.8/site-packages/portdatasplitter/main.py", line 61, in create_server
    self.serv.bind((ip, port))
OSError: [Errno 98] Address already in use

2021-05-04 10:57:41,876 - gravity_core.wlogger - ERROR - Traceback (most recent call last):
  File "/home/qodex/Gravity_core_export/gravity_core/wengine.py", line 76, in make_cps_connection
    self.cps.start()
  File "/home/qodex/.local/lib/python3.8/site-packages/portdatasplitter/main.py", line 37, in start
    self.create_server(self.server_ip, self.server_port)
  File "/home/qodex/.local/lib/python3.8/site-packages/portdatasplitter/main.py", line 61, in create_server
    self.serv.bind((ip, port))
OSError: [Errno 98] Address already in use

2021-05-04 10:57:46,884 - gravity_core.wlogger - ERROR - Traceback (most recent call last):
  File "/home/qodex/Gravity_core_export/gravity_core/wengine.py", line 76, in make_cps_connection
    self.cps.start()
  File "/home/qodex/.local/lib/python3.8/site-packages/portdatasplitter/main.py", line 37, in start
    self.create_server(self.server_ip, self.server_port)
  File "/home/qodex/.local/lib/python3.8/site-packages/portdatasplitter/main.py", line 61, in create_server
    self.serv.bind((ip, port))
OSError: [Errno 98] Address already in use

2021-05-04 10:57:51,892 - gravity_core.wlogger - ERROR - Traceback (most recent call last):
  File "/home/qodex/Gravity_core_export/gravity_core/wengine.py", line 76, in make_cps_connection
    self.cps.start()
  File "/home/qodex/.local/lib/python3.8/site-packages/portdatasplitter/main.py", line 37, in start
    self.create_server(self.server_ip, self.server_port)
  File "/home/qodex/.local/lib/python3.8/site-packages/portdatasplitter/main.py", line 61, in create_server
    self.serv.bind((ip, port))
OSError: [Errno 98] Address already in use

2021-05-04 10:57:56,900 - gravity_core.wlogger - ERROR - Traceback (most recent call last):
  File "/home/qodex/Gravity_core_export/gravity_core/wengine.py", line 76, in make_cps_connection
    self.cps.start()
  File "/home/qodex/.local/lib/python3.8/site-packages/portdatasplitter/main.py", line 37, in start
    self.create_server(self.server_ip, self.server_port)
  File "/home/qodex/.local/lib/python3.8/site-packages/portdatasplitter/main.py", line 61, in create_server
    self.serv.bind((ip, port))
OSError: [Errno 98] Address already in use

2021-05-04 10:58:01,908 - gravity_core.wlogger - ERROR - Traceback (most recent call last):
  File "/home/qodex/Gravity_core_export/gravity_core/wengine.py", line 76, in make_cps_connection
    self.cps.start()
  File "/home/qodex/.local/lib/python3.8/site-packages/portdatasplitter/main.py", line 37, in start
    self.create_server(self.server_ip, self.server_port)
  File "/home/qodex/.local/lib/python3.8/site-packages/portdatasplitter/main.py", line 61, in create_server
    self.serv.bind((ip, port))
OSError: [Errno 98] Address already in use

2021-05-04 10:58:06,916 - gravity_core.wlogger - ERROR - Traceback (most recent call last):
  File "/home/qodex/Gravity_core_export/gravity_core/wengine.py", line 76, in make_cps_connection
    self.cps.start()
  File "/home/qodex/.local/lib/python3.8/site-packages/portdatasplitter/main.py", line 37, in start
    self.create_server(self.server_ip, self.server_port)
  File "/home/qodex/.local/lib/python3.8/site-packages/portdatasplitter/main.py", line 61, in create_server
    self.serv.bind((ip, port))
OSError: [Errno 98] Address already in use

2021-05-04 10:58:11,924 - gravity_core.wlogger - ERROR - Traceback (most recent call last):
  File "/home/qodex/Gravity_core_export/gravity_core/wengine.py", line 76, in make_cps_connection
    self.cps.start()
  File "/home/qodex/.local/lib/python3.8/site-packages/portdatasplitter/main.py", line 37, in start
    self.create_server(self.server_ip, self.server_port)
  File "/home/qodex/.local/lib/python3.8/site-packages/portdatasplitter/main.py", line 61, in create_server
    self.serv.bind((ip, port))
OSError: [Errno 98] Address already in use

2021-05-04 10:58:16,931 - gravity_core.wlogger - ERROR - Traceback (most recent call last):
  File "/home/qodex/Gravity_core_export/gravity_core/wengine.py", line 76, in make_cps_connection
    self.cps.start()
  File "/home/qodex/.local/lib/python3.8/site-packages/portdatasplitter/main.py", line 37, in start
    self.create_server(self.server_ip, self.server_port)
  File "/home/qodex/.local/lib/python3.8/site-packages/portdatasplitter/main.py", line 61, in create_server
    self.serv.bind((ip, port))
OSError: [Errno 98] Address already in use

2021-05-04 10:58:21,938 - gravity_core.wlogger - ERROR - Traceback (most recent call last):
  File "/home/qodex/Gravity_core_export/gravity_core/wengine.py", line 76, in make_cps_connection
    self.cps.start()
  File "/home/qodex/.local/lib/python3.8/site-packages/portdatasplitter/main.py", line 37, in start
    self.create_server(self.server_ip, self.server_port)
  File "/home/qodex/.local/lib/python3.8/site-packages/portdatasplitter/main.py", line 61, in create_server
    self.serv.bind((ip, port))
OSError: [Errno 98] Address already in use

2021-05-04 10:58:26,943 - gravity_core.wlogger - ERROR - Traceback (most recent call last):
  File "/home/qodex/Gravity_core_export/gravity_core/wengine.py", line 76, in make_cps_connection
    self.cps.start()
  File "/home/qodex/.local/lib/python3.8/site-packages/portdatasplitter/main.py", line 37, in start
    self.create_server(self.server_ip, self.server_port)
  File "/home/qodex/.local/lib/python3.8/site-packages/portdatasplitter/main.py", line 61, in create_server
    self.serv.bind((ip, port))
OSError: [Errno 98] Address already in use

2021-05-04 10:58:31,951 - gravity_core.wlogger - ERROR - Traceback (most recent call last):
  File "/home/qodex/Gravity_core_export/gravity_core/wengine.py", line 76, in make_cps_connection
    self.cps.start()
  File "/home/qodex/.local/lib/python3.8/site-packages/portdatasplitter/main.py", line 37, in start
    self.create_server(self.server_ip, self.server_port)
  File "/home/qodex/.local/lib/python3.8/site-packages/portdatasplitter/main.py", line 61, in create_server
    self.serv.bind((ip, port))
OSError: [Errno 98] Address already in use

2021-05-04 10:58:36,959 - gravity_core.wlogger - ERROR - Traceback (most recent call last):
  File "/home/qodex/Gravity_core_export/gravity_core/wengine.py", line 76, in make_cps_connection
    self.cps.start()
  File "/home/qodex/.local/lib/python3.8/site-packages/portdatasplitter/main.py", line 37, in start
    self.create_server(self.server_ip, self.server_port)
  File "/home/qodex/.local/lib/python3.8/site-packages/portdatasplitter/main.py", line 61, in create_server
    self.serv.bind((ip, port))
OSError: [Errno 98] Address already in use

2021-05-04 10:58:41,967 - gravity_core.wlogger - ERROR - Traceback (most recent call last):
  File "/home/qodex/Gravity_core_export/gravity_core/wengine.py", line 76, in make_cps_connection
    self.cps.start()
  File "/home/qodex/.local/lib/python3.8/site-packages/portdatasplitter/main.py", line 37, in start
    self.create_server(self.server_ip, self.server_port)
  File "/home/qodex/.local/lib/python3.8/site-packages/portdatasplitter/main.py", line 61, in create_server
    self.serv.bind((ip, port))
OSError: [Errno 98] Address already in use

2021-05-04 10:58:46,976 - gravity_core.wlogger - ERROR - Traceback (most recent call last):
  File "/home/qodex/Gravity_core_export/gravity_core/wengine.py", line 76, in make_cps_connection
    self.cps.start()
  File "/home/qodex/.local/lib/python3.8/site-packages/portdatasplitter/main.py", line 37, in start
    self.create_server(self.server_ip, self.server_port)
  File "/home/qodex/.local/lib/python3.8/site-packages/portdatasplitter/main.py", line 61, in create_server
    self.serv.bind((ip, port))
OSError: [Errno 98] Address already in use

2021-05-04 10:58:51,984 - gravity_core.wlogger - ERROR - Traceback (most recent call last):
  File "/home/qodex/Gravity_core_export/gravity_core/wengine.py", line 76, in make_cps_connection
    self.cps.start()
  File "/home/qodex/.local/lib/python3.8/site-packages/portdatasplitter/main.py", line 37, in start
    self.create_server(self.server_ip, self.server_port)
  File "/home/qodex/.local/lib/python3.8/site-packages/portdatasplitter/main.py", line 61, in create_server
    self.serv.bind((ip, port))
OSError: [Errno 98] Address already in use

2021-05-04 10:58:56,991 - gravity_core.wlogger - ERROR - Traceback (most recent call last):
  File "/home/qodex/Gravity_core_export/gravity_core/wengine.py", line 76, in make_cps_connection
    self.cps.start()
  File "/home/qodex/.local/lib/python3.8/site-packages/portdatasplitter/main.py", line 37, in start
    self.create_server(self.server_ip, self.server_port)
  File "/home/qodex/.local/lib/python3.8/site-packages/portdatasplitter/main.py", line 61, in create_server
    self.serv.bind((ip, port))
OSError: [Errno 98] Address already in use

2021-05-04 10:59:01,999 - gravity_core.wlogger - ERROR - Traceback (most recent call last):
  File "/home/qodex/Gravity_core_export/gravity_core/wengine.py", line 76, in make_cps_connection
    self.cps.start()
  File "/home/qodex/.local/lib/python3.8/site-packages/portdatasplitter/main.py", line 37, in start
    self.create_server(self.server_ip, self.server_port)
  File "/home/qodex/.local/lib/python3.8/site-packages/portdatasplitter/main.py", line 61, in create_server
    self.serv.bind((ip, port))
OSError: [Errno 98] Address already in use

2021-05-04 10:59:07,007 - gravity_core.wlogger - ERROR - Traceback (most recent call last):
  File "/home/qodex/Gravity_core_export/gravity_core/wengine.py", line 76, in make_cps_connection
    self.cps.start()
  File "/home/qodex/.local/lib/python3.8/site-packages/portdatasplitter/main.py", line 37, in start
    self.create_server(self.server_ip, self.server_port)
  File "/home/qodex/.local/lib/python3.8/site-packages/portdatasplitter/main.py", line 61, in create_server
    self.serv.bind((ip, port))
OSError: [Errno 98] Address already in use

2021-05-04 10:59:12,011 - gravity_core.wlogger - ERROR - Traceback (most recent call last):
  File "/home/qodex/Gravity_core_export/gravity_core/wengine.py", line 76, in make_cps_connection
    self.cps.start()
  File "/home/qodex/.local/lib/python3.8/site-packages/portdatasplitter/main.py", line 37, in start
    self.create_server(self.server_ip, self.server_port)
  File "/home/qodex/.local/lib/python3.8/site-packages/portdatasplitter/main.py", line 61, in create_server
    self.serv.bind((ip, port))
OSError: [Errno 98] Address already in use

2021-05-04 10:59:17,019 - gravity_core.wlogger - ERROR - Traceback (most recent call last):
  File "/home/qodex/Gravity_core_export/gravity_core/wengine.py", line 76, in make_cps_connection
    self.cps.start()
  File "/home/qodex/.local/lib/python3.8/site-packages/portdatasplitter/main.py", line 37, in start
    self.create_server(self.server_ip, self.server_port)
  File "/home/qodex/.local/lib/python3.8/site-packages/portdatasplitter/main.py", line 61, in create_server
    self.serv.bind((ip, port))
OSError: [Errno 98] Address already in use

2021-05-04 10:59:22,025 - gravity_core.wlogger - ERROR - Traceback (most recent call last):
  File "/home/qodex/Gravity_core_export/gravity_core/wengine.py", line 76, in make_cps_connection
    self.cps.start()
  File "/home/qodex/.local/lib/python3.8/site-packages/portdatasplitter/main.py", line 37, in start
    self.create_server(self.server_ip, self.server_port)
  File "/home/qodex/.local/lib/python3.8/site-packages/portdatasplitter/main.py", line 61, in create_server
    self.serv.bind((ip, port))
OSError: [Errno 98] Address already in use

2021-05-04 10:59:27,033 - gravity_core.wlogger - ERROR - Traceback (most recent call last):
  File "/home/qodex/Gravity_core_export/gravity_core/wengine.py", line 76, in make_cps_connection
    self.cps.start()
  File "/home/qodex/.local/lib/python3.8/site-packages/portdatasplitter/main.py", line 37, in start
    self.create_server(self.server_ip, self.server_port)
  File "/home/qodex/.local/lib/python3.8/site-packages/portdatasplitter/main.py", line 61, in create_server
    self.serv.bind((ip, port))
OSError: [Errno 98] Address already in use

2021-05-04 10:59:32,041 - gravity_core.wlogger - ERROR - Traceback (most recent call last):
  File "/home/qodex/Gravity_core_export/gravity_core/wengine.py", line 76, in make_cps_connection
    self.cps.start()
  File "/home/qodex/.local/lib/python3.8/site-packages/portdatasplitter/main.py", line 37, in start
    self.create_server(self.server_ip, self.server_port)
  File "/home/qodex/.local/lib/python3.8/site-packages/portdatasplitter/main.py", line 61, in create_server
    self.serv.bind((ip, port))
OSError: [Errno 98] Address already in use

2021-05-04 10:59:37,048 - gravity_core.wlogger - ERROR - Traceback (most recent call last):
  File "/home/qodex/Gravity_core_export/gravity_core/wengine.py", line 76, in make_cps_connection
    self.cps.start()
  File "/home/qodex/.local/lib/python3.8/site-packages/portdatasplitter/main.py", line 37, in start
    self.create_server(self.server_ip, self.server_port)
  File "/home/qodex/.local/lib/python3.8/site-packages/portdatasplitter/main.py", line 61, in create_server
    self.serv.bind((ip, port))
OSError: [Errno 98] Address already in use

2021-05-04 10:59:42,056 - gravity_core.wlogger - ERROR - Traceback (most recent call last):
  File "/home/qodex/Gravity_core_export/gravity_core/wengine.py", line 76, in make_cps_connection
    self.cps.start()
  File "/home/qodex/.local/lib/python3.8/site-packages/portdatasplitter/main.py", line 37, in start
    self.create_server(self.server_ip, self.server_port)
  File "/home/qodex/.local/lib/python3.8/site-packages/portdatasplitter/main.py", line 61, in create_server
    self.serv.bind((ip, port))
OSError: [Errno 98] Address already in use

2021-05-04 10:59:47,064 - gravity_core.wlogger - ERROR - Traceback (most recent call last):
  File "/home/qodex/Gravity_core_export/gravity_core/wengine.py", line 76, in make_cps_connection
    self.cps.start()
  File "/home/qodex/.local/lib/python3.8/site-packages/portdatasplitter/main.py", line 37, in start
    self.create_server(self.server_ip, self.server_port)
  File "/home/qodex/.local/lib/python3.8/site-packages/portdatasplitter/main.py", line 61, in create_server
    self.serv.bind((ip, port))
OSError: [Errno 98] Address already in use

2021-05-04 10:59:52,072 - gravity_core.wlogger - ERROR - Traceback (most recent call last):
  File "/home/qodex/Gravity_core_export/gravity_core/wengine.py", line 76, in make_cps_connection
    self.cps.start()
  File "/home/qodex/.local/lib/python3.8/site-packages/portdatasplitter/main.py", line 37, in start
    self.create_server(self.server_ip, self.server_port)
  File "/home/qodex/.local/lib/python3.8/site-packages/portdatasplitter/main.py", line 61, in create_server
    self.serv.bind((ip, port))
OSError: [Errno 98] Address already in use

2021-05-04 10:59:57,079 - gravity_core.wlogger - ERROR - Traceback (most recent call last):
  File "/home/qodex/Gravity_core_export/gravity_core/wengine.py", line 76, in make_cps_connection
    self.cps.start()
  File "/home/qodex/.local/lib/python3.8/site-packages/portdatasplitter/main.py", line 37, in start
    self.create_server(self.server_ip, self.server_port)
  File "/home/qodex/.local/lib/python3.8/site-packages/portdatasplitter/main.py", line 61, in create_server
    self.serv.bind((ip, port))
OSError: [Errno 98] Address already in use

2021-05-04 11:00:02,084 - gravity_core.wlogger - ERROR - Traceback (most recent call last):
  File "/home/qodex/Gravity_core_export/gravity_core/wengine.py", line 76, in make_cps_connection
    self.cps.start()
  File "/home/qodex/.local/lib/python3.8/site-packages/portdatasplitter/main.py", line 37, in start
    self.create_server(self.server_ip, self.server_port)
  File "/home/qodex/.local/lib/python3.8/site-packages/portdatasplitter/main.py", line 61, in create_server
    self.serv.bind((ip, port))
OSError: [Errno 98] Address already in use

2021-05-04 11:00:07,092 - gravity_core.wlogger - ERROR - Traceback (most recent call last):
  File "/home/qodex/Gravity_core_export/gravity_core/wengine.py", line 76, in make_cps_connection
    self.cps.start()
  File "/home/qodex/.local/lib/python3.8/site-packages/portdatasplitter/main.py", line 37, in start
    self.create_server(self.server_ip, self.server_port)
  File "/home/qodex/.local/lib/python3.8/site-packages/portdatasplitter/main.py", line 61, in create_server
    self.serv.bind((ip, port))
OSError: [Errno 98] Address already in use

2021-05-04 11:00:12,100 - gravity_core.wlogger - ERROR - Traceback (most recent call last):
  File "/home/qodex/Gravity_core_export/gravity_core/wengine.py", line 76, in make_cps_connection
    self.cps.start()
  File "/home/qodex/.local/lib/python3.8/site-packages/portdatasplitter/main.py", line 37, in start
    self.create_server(self.server_ip, self.server_port)
  File "/home/qodex/.local/lib/python3.8/site-packages/portdatasplitter/main.py", line 61, in create_server
    self.serv.bind((ip, port))
OSError: [Errno 98] Address already in use

2021-05-04 11:00:17,108 - gravity_core.wlogger - ERROR - Traceback (most recent call last):
  File "/home/qodex/Gravity_core_export/gravity_core/wengine.py", line 76, in make_cps_connection
    self.cps.start()
  File "/home/qodex/.local/lib/python3.8/site-packages/portdatasplitter/main.py", line 37, in start
    self.create_server(self.server_ip, self.server_port)
  File "/home/qodex/.local/lib/python3.8/site-packages/portdatasplitter/main.py", line 61, in create_server
    self.serv.bind((ip, port))
OSError: [Errno 98] Address already in use

2021-05-04 11:00:22,116 - gravity_core.wlogger - ERROR - Traceback (most recent call last):
  File "/home/qodex/Gravity_core_export/gravity_core/wengine.py", line 76, in make_cps_connection
    self.cps.start()
  File "/home/qodex/.local/lib/python3.8/site-packages/portdatasplitter/main.py", line 37, in start
    self.create_server(self.server_ip, self.server_port)
  File "/home/qodex/.local/lib/python3.8/site-packages/portdatasplitter/main.py", line 61, in create_server
    self.serv.bind((ip, port))
OSError: [Errno 98] Address already in use

2021-05-04 11:00:27,125 - gravity_core.wlogger - ERROR - Traceback (most recent call last):
  File "/home/qodex/Gravity_core_export/gravity_core/wengine.py", line 76, in make_cps_connection
    self.cps.start()
  File "/home/qodex/.local/lib/python3.8/site-packages/portdatasplitter/main.py", line 37, in start
    self.create_server(self.server_ip, self.server_port)
  File "/home/qodex/.local/lib/python3.8/site-packages/portdatasplitter/main.py", line 61, in create_server
    self.serv.bind((ip, port))
OSError: [Errno 98] Address already in use

2021-05-04 11:00:32,132 - gravity_core.wlogger - ERROR - Traceback (most recent call last):
  File "/home/qodex/Gravity_core_export/gravity_core/wengine.py", line 76, in make_cps_connection
    self.cps.start()
  File "/home/qodex/.local/lib/python3.8/site-packages/portdatasplitter/main.py", line 37, in start
    self.create_server(self.server_ip, self.server_port)
  File "/home/qodex/.local/lib/python3.8/site-packages/portdatasplitter/main.py", line 61, in create_server
    self.serv.bind((ip, port))
OSError: [Errno 98] Address already in use

2021-05-04 11:00:37,140 - gravity_core.wlogger - ERROR - Traceback (most recent call last):
  File "/home/qodex/Gravity_core_export/gravity_core/wengine.py", line 76, in make_cps_connection
    self.cps.start()
  File "/home/qodex/.local/lib/python3.8/site-packages/portdatasplitter/main.py", line 37, in start
    self.create_server(self.server_ip, self.server_port)
  File "/home/qodex/.local/lib/python3.8/site-packages/portdatasplitter/main.py", line 61, in create_server
    self.serv.bind((ip, port))
OSError: [Errno 98] Address already in use

2021-05-04 11:00:42,148 - gravity_core.wlogger - ERROR - Traceback (most recent call last):
  File "/home/qodex/Gravity_core_export/gravity_core/wengine.py", line 76, in make_cps_connection
    self.cps.start()
  File "/home/qodex/.local/lib/python3.8/site-packages/portdatasplitter/main.py", line 37, in start
    self.create_server(self.server_ip, self.server_port)
  File "/home/qodex/.local/lib/python3.8/site-packages/portdatasplitter/main.py", line 61, in create_server
    self.serv.bind((ip, port))
OSError: [Errno 98] Address already in use

2021-05-04 11:00:47,153 - gravity_core.wlogger - ERROR - Traceback (most recent call last):
  File "/home/qodex/Gravity_core_export/gravity_core/wengine.py", line 76, in make_cps_connection
    self.cps.start()
  File "/home/qodex/.local/lib/python3.8/site-packages/portdatasplitter/main.py", line 37, in start
    self.create_server(self.server_ip, self.server_port)
  File "/home/qodex/.local/lib/python3.8/site-packages/portdatasplitter/main.py", line 61, in create_server
    self.serv.bind((ip, port))
OSError: [Errno 98] Address already in use

2021-05-04 11:00:52,162 - gravity_core.wlogger - ERROR - Traceback (most recent call last):
  File "/home/qodex/Gravity_core_export/gravity_core/wengine.py", line 76, in make_cps_connection
    self.cps.start()
  File "/home/qodex/.local/lib/python3.8/site-packages/portdatasplitter/main.py", line 37, in start
    self.create_server(self.server_ip, self.server_port)
  File "/home/qodex/.local/lib/python3.8/site-packages/portdatasplitter/main.py", line 61, in create_server
    self.serv.bind((ip, port))
OSError: [Errno 98] Address already in use

2021-05-04 11:00:57,168 - gravity_core.wlogger - ERROR - Traceback (most recent call last):
  File "/home/qodex/Gravity_core_export/gravity_core/wengine.py", line 76, in make_cps_connection
    self.cps.start()
  File "/home/qodex/.local/lib/python3.8/site-packages/portdatasplitter/main.py", line 37, in start
    self.create_server(self.server_ip, self.server_port)
  File "/home/qodex/.local/lib/python3.8/site-packages/portdatasplitter/main.py", line 61, in create_server
    self.serv.bind((ip, port))
OSError: [Errno 98] Address already in use

2021-05-04 11:01:02,176 - gravity_core.wlogger - ERROR - Traceback (most recent call last):
  File "/home/qodex/Gravity_core_export/gravity_core/wengine.py", line 76, in make_cps_connection
    self.cps.start()
  File "/home/qodex/.local/lib/python3.8/site-packages/portdatasplitter/main.py", line 37, in start
    self.create_server(self.server_ip, self.server_port)
  File "/home/qodex/.local/lib/python3.8/site-packages/portdatasplitter/main.py", line 61, in create_server
    self.serv.bind((ip, port))
OSError: [Errno 98] Address already in use

2021-05-04 11:01:07,184 - gravity_core.wlogger - ERROR - Traceback (most recent call last):
  File "/home/qodex/Gravity_core_export/gravity_core/wengine.py", line 76, in make_cps_connection
    self.cps.start()
  File "/home/qodex/.local/lib/python3.8/site-packages/portdatasplitter/main.py", line 37, in start
    self.create_server(self.server_ip, self.server_port)
  File "/home/qodex/.local/lib/python3.8/site-packages/portdatasplitter/main.py", line 61, in create_server
    self.serv.bind((ip, port))
OSError: [Errno 98] Address already in use

2021-05-04 11:01:12,192 - gravity_core.wlogger - ERROR - Traceback (most recent call last):
  File "/home/qodex/Gravity_core_export/gravity_core/wengine.py", line 76, in make_cps_connection
    self.cps.start()
  File "/home/qodex/.local/lib/python3.8/site-packages/portdatasplitter/main.py", line 37, in start
    self.create_server(self.server_ip, self.server_port)
  File "/home/qodex/.local/lib/python3.8/site-packages/portdatasplitter/main.py", line 61, in create_server
    self.serv.bind((ip, port))
OSError: [Errno 98] Address already in use

2021-05-04 11:01:17,200 - gravity_core.wlogger - ERROR - Traceback (most recent call last):
  File "/home/qodex/Gravity_core_export/gravity_core/wengine.py", line 76, in make_cps_connection
    self.cps.start()
  File "/home/qodex/.local/lib/python3.8/site-packages/portdatasplitter/main.py", line 37, in start
    self.create_server(self.server_ip, self.server_port)
  File "/home/qodex/.local/lib/python3.8/site-packages/portdatasplitter/main.py", line 61, in create_server
    self.serv.bind((ip, port))
OSError: [Errno 98] Address already in use

2021-05-04 11:01:22,208 - gravity_core.wlogger - ERROR - Traceback (most recent call last):
  File "/home/qodex/Gravity_core_export/gravity_core/wengine.py", line 76, in make_cps_connection
    self.cps.start()
  File "/home/qodex/.local/lib/python3.8/site-packages/portdatasplitter/main.py", line 37, in start
    self.create_server(self.server_ip, self.server_port)
  File "/home/qodex/.local/lib/python3.8/site-packages/portdatasplitter/main.py", line 61, in create_server
    self.serv.bind((ip, port))
OSError: [Errno 98] Address already in use

2021-05-04 11:01:27,216 - gravity_core.wlogger - ERROR - Traceback (most recent call last):
  File "/home/qodex/Gravity_core_export/gravity_core/wengine.py", line 76, in make_cps_connection
    self.cps.start()
  File "/home/qodex/.local/lib/python3.8/site-packages/portdatasplitter/main.py", line 37, in start
    self.create_server(self.server_ip, self.server_port)
  File "/home/qodex/.local/lib/python3.8/site-packages/portdatasplitter/main.py", line 61, in create_server
    self.serv.bind((ip, port))
OSError: [Errno 98] Address already in use

2021-05-04 11:01:32,225 - gravity_core.wlogger - ERROR - Traceback (most recent call last):
  File "/home/qodex/Gravity_core_export/gravity_core/wengine.py", line 76, in make_cps_connection
    self.cps.start()
  File "/home/qodex/.local/lib/python3.8/site-packages/portdatasplitter/main.py", line 37, in start
    self.create_server(self.server_ip, self.server_port)
  File "/home/qodex/.local/lib/python3.8/site-packages/portdatasplitter/main.py", line 61, in create_server
    self.serv.bind((ip, port))
OSError: [Errno 98] Address already in use

2021-05-04 11:01:37,232 - gravity_core.wlogger - ERROR - Traceback (most recent call last):
  File "/home/qodex/Gravity_core_export/gravity_core/wengine.py", line 76, in make_cps_connection
    self.cps.start()
  File "/home/qodex/.local/lib/python3.8/site-packages/portdatasplitter/main.py", line 37, in start
    self.create_server(self.server_ip, self.server_port)
  File "/home/qodex/.local/lib/python3.8/site-packages/portdatasplitter/main.py", line 61, in create_server
    self.serv.bind((ip, port))
OSError: [Errno 98] Address already in use

2021-05-04 11:01:42,240 - gravity_core.wlogger - ERROR - Traceback (most recent call last):
  File "/home/qodex/Gravity_core_export/gravity_core/wengine.py", line 76, in make_cps_connection
    self.cps.start()
  File "/home/qodex/.local/lib/python3.8/site-packages/portdatasplitter/main.py", line 37, in start
    self.create_server(self.server_ip, self.server_port)
  File "/home/qodex/.local/lib/python3.8/site-packages/portdatasplitter/main.py", line 61, in create_server
    self.serv.bind((ip, port))
OSError: [Errno 98] Address already in use

2021-05-04 11:01:47,248 - gravity_core.wlogger - ERROR - Traceback (most recent call last):
  File "/home/qodex/Gravity_core_export/gravity_core/wengine.py", line 76, in make_cps_connection
    self.cps.start()
  File "/home/qodex/.local/lib/python3.8/site-packages/portdatasplitter/main.py", line 37, in start
    self.create_server(self.server_ip, self.server_port)
  File "/home/qodex/.local/lib/python3.8/site-packages/portdatasplitter/main.py", line 61, in create_server
    self.serv.bind((ip, port))
OSError: [Errno 98] Address already in use

2021-05-04 11:01:52,256 - gravity_core.wlogger - ERROR - Traceback (most recent call last):
  File "/home/qodex/Gravity_core_export/gravity_core/wengine.py", line 76, in make_cps_connection
    self.cps.start()
  File "/home/qodex/.local/lib/python3.8/site-packages/portdatasplitter/main.py", line 37, in start
    self.create_server(self.server_ip, self.server_port)
  File "/home/qodex/.local/lib/python3.8/site-packages/portdatasplitter/main.py", line 61, in create_server
    self.serv.bind((ip, port))
OSError: [Errno 98] Address already in use

2021-05-04 11:01:57,265 - gravity_core.wlogger - ERROR - Traceback (most recent call last):
  File "/home/qodex/Gravity_core_export/gravity_core/wengine.py", line 76, in make_cps_connection
    self.cps.start()
  File "/home/qodex/.local/lib/python3.8/site-packages/portdatasplitter/main.py", line 37, in start
    self.create_server(self.server_ip, self.server_port)
  File "/home/qodex/.local/lib/python3.8/site-packages/portdatasplitter/main.py", line 61, in create_server
    self.serv.bind((ip, port))
OSError: [Errno 98] Address already in use

2021-05-04 11:02:02,272 - gravity_core.wlogger - ERROR - Traceback (most recent call last):
  File "/home/qodex/Gravity_core_export/gravity_core/wengine.py", line 76, in make_cps_connection
    self.cps.start()
  File "/home/qodex/.local/lib/python3.8/site-packages/portdatasplitter/main.py", line 37, in start
    self.create_server(self.server_ip, self.server_port)
  File "/home/qodex/.local/lib/python3.8/site-packages/portdatasplitter/main.py", line 61, in create_server
    self.serv.bind((ip, port))
OSError: [Errno 98] Address already in use

2021-05-04 11:02:07,280 - gravity_core.wlogger - ERROR - Traceback (most recent call last):
  File "/home/qodex/Gravity_core_export/gravity_core/wengine.py", line 76, in make_cps_connection
    self.cps.start()
  File "/home/qodex/.local/lib/python3.8/site-packages/portdatasplitter/main.py", line 37, in start
    self.create_server(self.server_ip, self.server_port)
  File "/home/qodex/.local/lib/python3.8/site-packages/portdatasplitter/main.py", line 61, in create_server
    self.serv.bind((ip, port))
OSError: [Errno 98] Address already in use

2021-05-04 11:02:12,286 - gravity_core.wlogger - ERROR - Traceback (most recent call last):
  File "/home/qodex/Gravity_core_export/gravity_core/wengine.py", line 76, in make_cps_connection
    self.cps.start()
  File "/home/qodex/.local/lib/python3.8/site-packages/portdatasplitter/main.py", line 37, in start
    self.create_server(self.server_ip, self.server_port)
  File "/home/qodex/.local/lib/python3.8/site-packages/portdatasplitter/main.py", line 61, in create_server
    self.serv.bind((ip, port))
OSError: [Errno 98] Address already in use

2021-05-04 11:02:17,294 - gravity_core.wlogger - ERROR - Traceback (most recent call last):
  File "/home/qodex/Gravity_core_export/gravity_core/wengine.py", line 76, in make_cps_connection
    self.cps.start()
  File "/home/qodex/.local/lib/python3.8/site-packages/portdatasplitter/main.py", line 37, in start
    self.create_server(self.server_ip, self.server_port)
  File "/home/qodex/.local/lib/python3.8/site-packages/portdatasplitter/main.py", line 61, in create_server
    self.serv.bind((ip, port))
OSError: [Errno 98] Address already in use

2021-05-04 11:02:22,300 - gravity_core.wlogger - ERROR - Traceback (most recent call last):
  File "/home/qodex/Gravity_core_export/gravity_core/wengine.py", line 76, in make_cps_connection
    self.cps.start()
  File "/home/qodex/.local/lib/python3.8/site-packages/portdatasplitter/main.py", line 37, in start
    self.create_server(self.server_ip, self.server_port)
  File "/home/qodex/.local/lib/python3.8/site-packages/portdatasplitter/main.py", line 61, in create_server
    self.serv.bind((ip, port))
OSError: [Errno 98] Address already in use

2021-05-04 11:02:27,308 - gravity_core.wlogger - ERROR - Traceback (most recent call last):
  File "/home/qodex/Gravity_core_export/gravity_core/wengine.py", line 76, in make_cps_connection
    self.cps.start()
  File "/home/qodex/.local/lib/python3.8/site-packages/portdatasplitter/main.py", line 37, in start
    self.create_server(self.server_ip, self.server_port)
  File "/home/qodex/.local/lib/python3.8/site-packages/portdatasplitter/main.py", line 61, in create_server
    self.serv.bind((ip, port))
OSError: [Errno 98] Address already in use

2021-05-04 11:02:32,315 - gravity_core.wlogger - ERROR - Traceback (most recent call last):
  File "/home/qodex/Gravity_core_export/gravity_core/wengine.py", line 76, in make_cps_connection
    self.cps.start()
  File "/home/qodex/.local/lib/python3.8/site-packages/portdatasplitter/main.py", line 37, in start
    self.create_server(self.server_ip, self.server_port)
  File "/home/qodex/.local/lib/python3.8/site-packages/portdatasplitter/main.py", line 61, in create_server
    self.serv.bind((ip, port))
OSError: [Errno 98] Address already in use

2021-05-04 11:02:37,320 - gravity_core.wlogger - ERROR - Traceback (most recent call last):
  File "/home/qodex/Gravity_core_export/gravity_core/wengine.py", line 76, in make_cps_connection
    self.cps.start()
  File "/home/qodex/.local/lib/python3.8/site-packages/portdatasplitter/main.py", line 37, in start
    self.create_server(self.server_ip, self.server_port)
  File "/home/qodex/.local/lib/python3.8/site-packages/portdatasplitter/main.py", line 61, in create_server
    self.serv.bind((ip, port))
OSError: [Errno 98] Address already in use

2021-05-04 11:02:42,328 - gravity_core.wlogger - ERROR - Traceback (most recent call last):
  File "/home/qodex/Gravity_core_export/gravity_core/wengine.py", line 76, in make_cps_connection
    self.cps.start()
  File "/home/qodex/.local/lib/python3.8/site-packages/portdatasplitter/main.py", line 37, in start
    self.create_server(self.server_ip, self.server_port)
  File "/home/qodex/.local/lib/python3.8/site-packages/portdatasplitter/main.py", line 61, in create_server
    self.serv.bind((ip, port))
OSError: [Errno 98] Address already in use

2021-05-04 11:02:47,336 - gravity_core.wlogger - ERROR - Traceback (most recent call last):
  File "/home/qodex/Gravity_core_export/gravity_core/wengine.py", line 76, in make_cps_connection
    self.cps.start()
  File "/home/qodex/.local/lib/python3.8/site-packages/portdatasplitter/main.py", line 37, in start
    self.create_server(self.server_ip, self.server_port)
  File "/home/qodex/.local/lib/python3.8/site-packages/portdatasplitter/main.py", line 61, in create_server
    self.serv.bind((ip, port))
OSError: [Errno 98] Address already in use

2021-05-04 11:02:52,343 - gravity_core.wlogger - ERROR - Traceback (most recent call last):
  File "/home/qodex/Gravity_core_export/gravity_core/wengine.py", line 76, in make_cps_connection
    self.cps.start()
  File "/home/qodex/.local/lib/python3.8/site-packages/portdatasplitter/main.py", line 37, in start
    self.create_server(self.server_ip, self.server_port)
  File "/home/qodex/.local/lib/python3.8/site-packages/portdatasplitter/main.py", line 61, in create_server
    self.serv.bind((ip, port))
OSError: [Errno 98] Address already in use

2021-05-04 13:18:26,365 - gravity_core.wlogger - ERROR - Ошибка в работе оператора!
2021-05-04 13:18:26,365 - gravity_core.wlogger - ERROR - Traceback (most recent call last):
  File "Gravity_core_export/wlauncher.py", line 54, in _start
    self.gravity_core.work()
  File "/home/qodex/Gravity_core_export/gravity_core/wengine.py", line 1202, in work
    self.operate_skud_stream()
  File "/home/qodex/Gravity_core_export/gravity_core/wengine.py", line 1158, in operate_skud_stream
    self.car_detect_operate(rfid, course)
  File "/home/qodex/Gravity_core_export/gravity_core/wengine.py", line 1050, in car_detect_operate
    self.operateCM(rfid, course, idtype)
  File "/home/qodex/Gravity_core_export/gravity_core/wengine.py", line 1088, in operateCM
    must_be_tko = check_if_car_tko(self.sqlshell, carnum, s.asu_routes_table, s.auto)
  File "/home/qodex/Gravity_core_export/gravity_core/functions/asu_routes.py", line 8, in check_if_car_tko
    response = sqlshell.try_execute_get(command)[0][0]
KeyError: 0

2021-05-04 14:06:08,813 - gravity_core.wlogger - ERROR - Ошибка в работе оператора!
2021-05-04 14:06:08,814 - gravity_core.wlogger - ERROR - Traceback (most recent call last):
  File "wlauncher.py", line 54, in _start
    self.gravity_core.work()
  File "/home/qodex/Gravity_core_export/gravity_core/wengine.py", line 1204, in work
    self.operate_skud_stream()
  File "/home/qodex/Gravity_core_export/gravity_core/wengine.py", line 1160, in operate_skud_stream
    self.car_detect_operate(rfid, course)
  File "/home/qodex/Gravity_core_export/gravity_core/wengine.py", line 1051, in car_detect_operate
    self.operateCM(rfid, course, idtype)
  File "/home/qodex/Gravity_core_export/gravity_core/wengine.py", line 1115, in operateCM
    'have_brutto': have_brutto, 'must_be_tko': must_be_tko}}
UnboundLocalError: local variable 'must_be_tko' referenced before assignment

2021-05-04 14:08:31,097 - gravity_core.wlogger - ERROR - Выход не зафиксирован фотоэлементом
2021-05-04 14:11:22,449 - gravity_core.wlogger - ERROR - Выход не зафиксирован фотоэлементом
2021-05-04 14:23:35,751 - gravity_core.wlogger - ERROR - Ошибка в работе оператора!
2021-05-04 14:23:35,752 - gravity_core.wlogger - ERROR - Traceback (most recent call last):
  File "wlauncher.py", line 54, in _start
    self.gravity_core.work()
  File "/home/qodex/Gravity_core_export/gravity_core/wengine.py", line 1204, in work
    self.operate_skud_stream()
  File "/home/qodex/Gravity_core_export/gravity_core/wengine.py", line 1160, in operate_skud_stream
    self.car_detect_operate(rfid, course)
  File "/home/qodex/Gravity_core_export/gravity_core/wengine.py", line 1051, in car_detect_operate
    self.operateCM(rfid, course, idtype)
  File "/home/qodex/Gravity_core_export/gravity_core/wengine.py", line 1115, in operateCM
    'have_brutto': have_brutto, 'must_be_tko': must_be_tko}}
UnboundLocalError: local variable 'must_be_tko' referenced before assignment

2021-05-04 14:28:45,579 - gravity_core.wlogger - ERROR - Выход не зафиксирован фотоэлементом
2021-05-04 15:07:22,211 - gravity_core.wlogger - ERROR - Traceback (most recent call last):
  File "/home/qodex/Gravity_core_export/gravity_core/wlistener.py", line 102, in broadcastMsgSend
    conn.send(msg)
BrokenPipeError: [Errno 32] Broken pipe

2021-05-04 15:07:22,211 - gravity_core.wlogger - ERROR - Traceback (most recent call last):
  File "/home/qodex/Gravity_core_export/gravity_core/wlistener.py", line 102, in broadcastMsgSend
    conn.send(msg)
BrokenPipeError: [Errno 32] Broken pipe

2021-05-04 15:07:22,213 - gravity_core.wlogger - ERROR - Traceback (most recent call last):
  File "/home/qodex/Gravity_core_export/gravity_core/wlistener.py", line 102, in broadcastMsgSend
    conn.send(msg)
BrokenPipeError: [Errno 32] Broken pipe

2021-05-04 15:07:22,213 - gravity_core.wlogger - ERROR - Traceback (most recent call last):
  File "/home/qodex/Gravity_core_export/gravity_core/wlistener.py", line 102, in broadcastMsgSend
    conn.send(msg)
BrokenPipeError: [Errno 32] Broken pipe

2021-05-04 15:07:22,214 - gravity_core.wlogger - ERROR - Traceback (most recent call last):
  File "/home/qodex/Gravity_core_export/gravity_core/wlistener.py", line 102, in broadcastMsgSend
    conn.send(msg)
BrokenPipeError: [Errno 32] Broken pipe

2021-05-04 15:07:22,214 - gravity_core.wlogger - ERROR - Traceback (most recent call last):
  File "/home/qodex/Gravity_core_export/gravity_core/wlistener.py", line 102, in broadcastMsgSend
    conn.send(msg)
BrokenPipeError: [Errno 32] Broken pipe

2021-05-04 15:07:25,209 - gravity_core.wlogger - ERROR - Traceback (most recent call last):
  File "/home/qodex/Gravity_core_export/gravity_core/wlistener.py", line 102, in broadcastMsgSend
    conn.send(msg)
BrokenPipeError: [Errno 32] Broken pipe

2021-05-04 15:07:25,210 - gravity_core.wlogger - ERROR - Traceback (most recent call last):
  File "/home/qodex/Gravity_core_export/gravity_core/wlistener.py", line 102, in broadcastMsgSend
    conn.send(msg)
BrokenPipeError: [Errno 32] Broken pipe

2021-05-04 15:07:25,210 - gravity_core.wlogger - ERROR - Traceback (most recent call last):
  File "/home/qodex/Gravity_core_export/gravity_core/wlistener.py", line 102, in broadcastMsgSend
    conn.send(msg)
BrokenPipeError: [Errno 32] Broken pipe

2021-05-04 15:07:25,211 - gravity_core.wlogger - ERROR - Traceback (most recent call last):
  File "/home/qodex/Gravity_core_export/gravity_core/wlistener.py", line 102, in broadcastMsgSend
    conn.send(msg)
BrokenPipeError: [Errno 32] Broken pipe

2021-05-04 15:07:25,212 - gravity_core.wlogger - ERROR - Traceback (most recent call last):
  File "/home/qodex/Gravity_core_export/gravity_core/wlistener.py", line 102, in broadcastMsgSend
    conn.send(msg)
BrokenPipeError: [Errno 32] Broken pipe

2021-05-04 15:07:25,213 - gravity_core.wlogger - ERROR - Traceback (most recent call last):
  File "/home/qodex/Gravity_core_export/gravity_core/wlistener.py", line 102, in broadcastMsgSend
    conn.send(msg)
BrokenPipeError: [Errno 32] Broken pipe

2021-05-04 15:07:30,711 - gravity_core.wlogger - ERROR - Traceback (most recent call last):
  File "/home/qodex/Gravity_core_export/gravity_core/wlistener.py", line 102, in broadcastMsgSend
    conn.send(msg)
BrokenPipeError: [Errno 32] Broken pipe

2021-05-04 15:07:30,712 - gravity_core.wlogger - ERROR - Traceback (most recent call last):
  File "/home/qodex/Gravity_core_export/gravity_core/wlistener.py", line 102, in broadcastMsgSend
    conn.send(msg)
BrokenPipeError: [Errno 32] Broken pipe

2021-05-04 15:07:30,712 - gravity_core.wlogger - ERROR - Traceback (most recent call last):
  File "/home/qodex/Gravity_core_export/gravity_core/wlistener.py", line 102, in broadcastMsgSend
    conn.send(msg)
BrokenPipeError: [Errno 32] Broken pipe

2021-05-04 15:07:30,713 - gravity_core.wlogger - ERROR - Traceback (most recent call last):
  File "/home/qodex/Gravity_core_export/gravity_core/wlistener.py", line 102, in broadcastMsgSend
    conn.send(msg)
BrokenPipeError: [Errno 32] Broken pipe

2021-05-04 15:07:30,713 - gravity_core.wlogger - ERROR - Traceback (most recent call last):
  File "/home/qodex/Gravity_core_export/gravity_core/wlistener.py", line 102, in broadcastMsgSend
    conn.send(msg)
BrokenPipeError: [Errno 32] Broken pipe

2021-05-04 15:07:30,714 - gravity_core.wlogger - ERROR - Traceback (most recent call last):
  File "/home/qodex/Gravity_core_export/gravity_core/wlistener.py", line 102, in broadcastMsgSend
    conn.send(msg)
BrokenPipeError: [Errno 32] Broken pipe

2021-05-04 15:08:30,730 - gravity_core.wlogger - ERROR - Traceback (most recent call last):
  File "/home/qodex/Gravity_core_export/gravity_core/wlistener.py", line 102, in broadcastMsgSend
    conn.send(msg)
BrokenPipeError: [Errno 32] Broken pipe

2021-05-04 15:08:36,245 - gravity_core.wlogger - ERROR - Traceback (most recent call last):
  File "/home/qodex/Gravity_core_export/gravity_core/wlistener.py", line 102, in broadcastMsgSend
    conn.send(msg)
BrokenPipeError: [Errno 32] Broken pipe

2021-05-04 15:09:02,228 - gravity_core.wlogger - ERROR - Traceback (most recent call last):
  File "/home/qodex/Gravity_core_export/gravity_core/wlistener.py", line 102, in broadcastMsgSend
    conn.send(msg)
BrokenPipeError: [Errno 32] Broken pipe

2021-05-04 15:26:28,376 - gravity_core.wlogger - ERROR - Traceback (most recent call last):
  File "/home/qodex/Gravity_core_export/gravity_core/wlistener.py", line 102, in broadcastMsgSend
    conn.send(msg)
BrokenPipeError: [Errno 32] Broken pipe

2021-05-04 15:26:40,506 - gravity_core.wlogger - ERROR - Traceback (most recent call last):
  File "/home/qodex/Gravity_core_export/gravity_core/wlistener.py", line 102, in broadcastMsgSend
    conn.send(msg)
BrokenPipeError: [Errno 32] Broken pipe

2021-05-04 15:26:41,842 - gravity_core.wlogger - ERROR - Traceback (most recent call last):
  File "/home/qodex/Gravity_core_export/gravity_core/wlistener.py", line 102, in broadcastMsgSend
    conn.send(msg)
BrokenPipeError: [Errno 32] Broken pipe

2021-05-04 17:09:07,036 - gravity_core.wlogger - ERROR - Traceback (most recent call last):
  File "/home/qodex/Gravity_core_export/gravity_core/wlistener.py", line 102, in broadcastMsgSend
    conn.send(msg)
BrokenPipeError: [Errno 32] Broken pipe

2021-05-04 17:09:07,039 - gravity_core.wlogger - ERROR - Traceback (most recent call last):
  File "/home/qodex/Gravity_core_export/gravity_core/wlistener.py", line 102, in broadcastMsgSend
    conn.send(msg)
BrokenPipeError: [Errno 32] Broken pipe

2021-05-04 17:09:07,050 - gravity_core.wlogger - ERROR - Traceback (most recent call last):
  File "/home/qodex/Gravity_core_export/gravity_core/wlistener.py", line 102, in broadcastMsgSend
    conn.send(msg)
BrokenPipeError: [Errno 32] Broken pipe

2021-05-04 17:09:07,051 - gravity_core.wlogger - ERROR - Traceback (most recent call last):
  File "/home/qodex/Gravity_core_export/gravity_core/wlistener.py", line 102, in broadcastMsgSend
    conn.send(msg)
BrokenPipeError: [Errno 32] Broken pipe

2021-05-04 17:09:07,052 - gravity_core.wlogger - ERROR - Traceback (most recent call last):
  File "/home/qodex/Gravity_core_export/gravity_core/wlistener.py", line 102, in broadcastMsgSend
    conn.send(msg)
BrokenPipeError: [Errno 32] Broken pipe

2021-05-04 17:09:07,052 - gravity_core.wlogger - ERROR - Traceback (most recent call last):
  File "/home/qodex/Gravity_core_export/gravity_core/wlistener.py", line 102, in broadcastMsgSend
    conn.send(msg)
BrokenPipeError: [Errno 32] Broken pipe

2021-05-05 09:23:14,252 - gravity_core.wlogger - ERROR - Traceback (most recent call last):
  File "/home/qodex/Gravity_core_export/gravity_core/wlistener.py", line 102, in broadcastMsgSend
    conn.send(msg)
BrokenPipeError: [Errno 32] Broken pipe

2021-05-05 09:23:14,253 - gravity_core.wlogger - ERROR - Traceback (most recent call last):
  File "/home/qodex/Gravity_core_export/gravity_core/wlistener.py", line 102, in broadcastMsgSend
    conn.send(msg)
BrokenPipeError: [Errno 32] Broken pipe

2021-05-05 09:23:14,253 - gravity_core.wlogger - ERROR - Traceback (most recent call last):
  File "/home/qodex/Gravity_core_export/gravity_core/wlistener.py", line 102, in broadcastMsgSend
    conn.send(msg)
BrokenPipeError: [Errno 32] Broken pipe

2021-05-05 09:23:14,254 - gravity_core.wlogger - ERROR - Traceback (most recent call last):
  File "/home/qodex/Gravity_core_export/gravity_core/wlistener.py", line 102, in broadcastMsgSend
    conn.send(msg)
BrokenPipeError: [Errno 32] Broken pipe

2021-05-05 09:23:14,255 - gravity_core.wlogger - ERROR - Traceback (most recent call last):
  File "/home/qodex/Gravity_core_export/gravity_core/wlistener.py", line 102, in broadcastMsgSend
    conn.send(msg)
BrokenPipeError: [Errno 32] Broken pipe

2021-05-05 09:23:14,255 - gravity_core.wlogger - ERROR - Traceback (most recent call last):
  File "/home/qodex/Gravity_core_export/gravity_core/wlistener.py", line 102, in broadcastMsgSend
    conn.send(msg)
BrokenPipeError: [Errno 32] Broken pipe

2021-05-05 09:23:14,256 - gravity_core.wlogger - ERROR - Traceback (most recent call last):
  File "/home/qodex/Gravity_core_export/gravity_core/wlistener.py", line 102, in broadcastMsgSend
    conn.send(msg)
BrokenPipeError: [Errno 32] Broken pipe

2021-05-05 09:23:14,257 - gravity_core.wlogger - ERROR - Traceback (most recent call last):
  File "/home/qodex/Gravity_core_export/gravity_core/wlistener.py", line 102, in broadcastMsgSend
    conn.send(msg)
BrokenPipeError: [Errno 32] Broken pipe

2021-05-05 09:23:14,257 - gravity_core.wlogger - ERROR - Traceback (most recent call last):
  File "/home/qodex/Gravity_core_export/gravity_core/wlistener.py", line 102, in broadcastMsgSend
    conn.send(msg)
BrokenPipeError: [Errno 32] Broken pipe

2021-05-05 09:23:14,258 - gravity_core.wlogger - ERROR - Traceback (most recent call last):
  File "/home/qodex/Gravity_core_export/gravity_core/wlistener.py", line 102, in broadcastMsgSend
    conn.send(msg)
BrokenPipeError: [Errno 32] Broken pipe

2021-05-05 09:23:14,259 - gravity_core.wlogger - ERROR - Traceback (most recent call last):
  File "/home/qodex/Gravity_core_export/gravity_core/wlistener.py", line 102, in broadcastMsgSend
    conn.send(msg)
BrokenPipeError: [Errno 32] Broken pipe

2021-05-05 09:23:14,260 - gravity_core.wlogger - ERROR - Traceback (most recent call last):
  File "/home/qodex/Gravity_core_export/gravity_core/wlistener.py", line 102, in broadcastMsgSend
    conn.send(msg)
BrokenPipeError: [Errno 32] Broken pipe

2021-05-05 09:23:18,475 - gravity_core.wlogger - ERROR - Traceback (most recent call last):
  File "/home/qodex/Gravity_core_export/gravity_core/wlistener.py", line 102, in broadcastMsgSend
    conn.send(msg)
BrokenPipeError: [Errno 32] Broken pipe

2021-05-05 09:23:18,476 - gravity_core.wlogger - ERROR - Traceback (most recent call last):
  File "/home/qodex/Gravity_core_export/gravity_core/wlistener.py", line 102, in broadcastMsgSend
    conn.send(msg)
BrokenPipeError: [Errno 32] Broken pipe

2021-05-05 09:23:18,477 - gravity_core.wlogger - ERROR - Traceback (most recent call last):
  File "/home/qodex/Gravity_core_export/gravity_core/wlistener.py", line 102, in broadcastMsgSend
    conn.send(msg)
BrokenPipeError: [Errno 32] Broken pipe

2021-05-05 09:23:18,477 - gravity_core.wlogger - ERROR - Traceback (most recent call last):
  File "/home/qodex/Gravity_core_export/gravity_core/wlistener.py", line 102, in broadcastMsgSend
    conn.send(msg)
BrokenPipeError: [Errno 32] Broken pipe

2021-05-05 09:23:18,478 - gravity_core.wlogger - ERROR - Traceback (most recent call last):
  File "/home/qodex/Gravity_core_export/gravity_core/wlistener.py", line 102, in broadcastMsgSend
    conn.send(msg)
BrokenPipeError: [Errno 32] Broken pipe

2021-05-05 09:23:18,479 - gravity_core.wlogger - ERROR - Traceback (most recent call last):
  File "/home/qodex/Gravity_core_export/gravity_core/wlistener.py", line 102, in broadcastMsgSend
    conn.send(msg)
BrokenPipeError: [Errno 32] Broken pipe

2021-05-05 09:23:18,479 - gravity_core.wlogger - ERROR - Traceback (most recent call last):
  File "/home/qodex/Gravity_core_export/gravity_core/wlistener.py", line 102, in broadcastMsgSend
    conn.send(msg)
BrokenPipeError: [Errno 32] Broken pipe

2021-05-05 09:23:18,480 - gravity_core.wlogger - ERROR - Traceback (most recent call last):
  File "/home/qodex/Gravity_core_export/gravity_core/wlistener.py", line 102, in broadcastMsgSend
    conn.send(msg)
BrokenPipeError: [Errno 32] Broken pipe

2021-05-05 09:23:18,480 - gravity_core.wlogger - ERROR - Traceback (most recent call last):
  File "/home/qodex/Gravity_core_export/gravity_core/wlistener.py", line 102, in broadcastMsgSend
    conn.send(msg)
BrokenPipeError: [Errno 32] Broken pipe

2021-05-05 09:23:18,481 - gravity_core.wlogger - ERROR - Traceback (most recent call last):
  File "/home/qodex/Gravity_core_export/gravity_core/wlistener.py", line 102, in broadcastMsgSend
    conn.send(msg)
BrokenPipeError: [Errno 32] Broken pipe

2021-05-05 09:23:18,481 - gravity_core.wlogger - ERROR - Traceback (most recent call last):
  File "/home/qodex/Gravity_core_export/gravity_core/wlistener.py", line 102, in broadcastMsgSend
    conn.send(msg)
BrokenPipeError: [Errno 32] Broken pipe

2021-05-05 09:23:18,481 - gravity_core.wlogger - ERROR - Traceback (most recent call last):
  File "/home/qodex/Gravity_core_export/gravity_core/wlistener.py", line 102, in broadcastMsgSend
    conn.send(msg)
BrokenPipeError: [Errno 32] Broken pipe

2021-05-05 09:23:19,564 - gravity_core.wlogger - ERROR - Traceback (most recent call last):
  File "/home/qodex/Gravity_core_export/gravity_core/wlistener.py", line 102, in broadcastMsgSend
    conn.send(msg)
BrokenPipeError: [Errno 32] Broken pipe

2021-05-05 09:23:19,565 - gravity_core.wlogger - ERROR - Traceback (most recent call last):
  File "/home/qodex/Gravity_core_export/gravity_core/wlistener.py", line 102, in broadcastMsgSend
    conn.send(msg)
BrokenPipeError: [Errno 32] Broken pipe

2021-05-05 09:23:19,566 - gravity_core.wlogger - ERROR - Traceback (most recent call last):
  File "/home/qodex/Gravity_core_export/gravity_core/wlistener.py", line 102, in broadcastMsgSend
    conn.send(msg)
BrokenPipeError: [Errno 32] Broken pipe

2021-05-05 09:23:19,566 - gravity_core.wlogger - ERROR - Traceback (most recent call last):
  File "/home/qodex/Gravity_core_export/gravity_core/wlistener.py", line 102, in broadcastMsgSend
    conn.send(msg)
BrokenPipeError: [Errno 32] Broken pipe

2021-05-05 09:23:19,567 - gravity_core.wlogger - ERROR - Traceback (most recent call last):
  File "/home/qodex/Gravity_core_export/gravity_core/wlistener.py", line 102, in broadcastMsgSend
    conn.send(msg)
BrokenPipeError: [Errno 32] Broken pipe

2021-05-05 09:23:19,568 - gravity_core.wlogger - ERROR - Traceback (most recent call last):
  File "/home/qodex/Gravity_core_export/gravity_core/wlistener.py", line 102, in broadcastMsgSend
    conn.send(msg)
BrokenPipeError: [Errno 32] Broken pipe

2021-05-05 09:23:19,568 - gravity_core.wlogger - ERROR - Traceback (most recent call last):
  File "/home/qodex/Gravity_core_export/gravity_core/wlistener.py", line 102, in broadcastMsgSend
    conn.send(msg)
BrokenPipeError: [Errno 32] Broken pipe

2021-05-05 09:23:19,569 - gravity_core.wlogger - ERROR - Traceback (most recent call last):
  File "/home/qodex/Gravity_core_export/gravity_core/wlistener.py", line 102, in broadcastMsgSend
    conn.send(msg)
BrokenPipeError: [Errno 32] Broken pipe

2021-05-05 09:23:19,569 - gravity_core.wlogger - ERROR - Traceback (most recent call last):
  File "/home/qodex/Gravity_core_export/gravity_core/wlistener.py", line 102, in broadcastMsgSend
    conn.send(msg)
BrokenPipeError: [Errno 32] Broken pipe

2021-05-05 09:23:19,569 - gravity_core.wlogger - ERROR - Traceback (most recent call last):
  File "/home/qodex/Gravity_core_export/gravity_core/wlistener.py", line 102, in broadcastMsgSend
    conn.send(msg)
BrokenPipeError: [Errno 32] Broken pipe

2021-05-05 09:23:19,569 - gravity_core.wlogger - ERROR - Traceback (most recent call last):
  File "/home/qodex/Gravity_core_export/gravity_core/wlistener.py", line 102, in broadcastMsgSend
    conn.send(msg)
BrokenPipeError: [Errno 32] Broken pipe

2021-05-05 09:23:19,570 - gravity_core.wlogger - ERROR - Traceback (most recent call last):
  File "/home/qodex/Gravity_core_export/gravity_core/wlistener.py", line 102, in broadcastMsgSend
    conn.send(msg)
BrokenPipeError: [Errno 32] Broken pipe

2021-05-05 11:08:30,174 - gravity_core.wlogger - ERROR - Traceback (most recent call last):
  File "/home/qodex/Gravity_core_export/gravity_core/wlistener.py", line 102, in broadcastMsgSend
    conn.send(msg)
BrokenPipeError: [Errno 32] Broken pipe

2021-05-05 11:08:33,951 - gravity_core.wlogger - ERROR - Traceback (most recent call last):
  File "/home/qodex/Gravity_core_export/gravity_core/wlistener.py", line 102, in broadcastMsgSend
    conn.send(msg)
BrokenPipeError: [Errno 32] Broken pipe

2021-05-05 11:08:34,001 - gravity_core.wlogger - ERROR - Traceback (most recent call last):
  File "/home/qodex/Gravity_core_export/gravity_core/wlistener.py", line 102, in broadcastMsgSend
    conn.send(msg)
BrokenPipeError: [Errno 32] Broken pipe

2021-05-05 11:17:21,169 - gravity_core.wlogger - ERROR - Traceback (most recent call last):
  File "/home/qodex/Gravity_core_export/gravity_core/wlistener.py", line 102, in broadcastMsgSend
    conn.send(msg)
BrokenPipeError: [Errno 32] Broken pipe

2021-05-05 11:17:23,528 - gravity_core.wlogger - ERROR - Traceback (most recent call last):
  File "/home/qodex/Gravity_core_export/gravity_core/wlistener.py", line 102, in broadcastMsgSend
    conn.send(msg)
BrokenPipeError: [Errno 32] Broken pipe

2021-05-05 11:17:23,577 - gravity_core.wlogger - ERROR - Traceback (most recent call last):
  File "/home/qodex/Gravity_core_export/gravity_core/wlistener.py", line 102, in broadcastMsgSend
    conn.send(msg)
BrokenPipeError: [Errno 32] Broken pipe

2021-05-05 12:09:27,909 - gravity_core.wlogger - ERROR - Traceback (most recent call last):
  File "/home/qodex/Gravity_core_export/gravity_core/wengine.py", line 78, in make_cps_connection
    self.cps.start()
  File "/home/qodex/.local/lib/python3.8/site-packages/portdatasplitter/main.py", line 37, in start
    self.create_server(self.server_ip, self.server_port)
  File "/home/qodex/.local/lib/python3.8/site-packages/portdatasplitter/main.py", line 61, in create_server
    self.serv.bind((ip, port))
OSError: [Errno 98] Address already in use

2021-05-05 12:09:32,918 - gravity_core.wlogger - ERROR - Traceback (most recent call last):
  File "/home/qodex/Gravity_core_export/gravity_core/wengine.py", line 78, in make_cps_connection
    self.cps.start()
  File "/home/qodex/.local/lib/python3.8/site-packages/portdatasplitter/main.py", line 37, in start
    self.create_server(self.server_ip, self.server_port)
  File "/home/qodex/.local/lib/python3.8/site-packages/portdatasplitter/main.py", line 61, in create_server
    self.serv.bind((ip, port))
OSError: [Errno 98] Address already in use

2021-05-05 12:09:37,927 - gravity_core.wlogger - ERROR - Traceback (most recent call last):
  File "/home/qodex/Gravity_core_export/gravity_core/wengine.py", line 78, in make_cps_connection
    self.cps.start()
  File "/home/qodex/.local/lib/python3.8/site-packages/portdatasplitter/main.py", line 37, in start
    self.create_server(self.server_ip, self.server_port)
  File "/home/qodex/.local/lib/python3.8/site-packages/portdatasplitter/main.py", line 61, in create_server
    self.serv.bind((ip, port))
OSError: [Errno 98] Address already in use

2021-05-05 12:09:42,936 - gravity_core.wlogger - ERROR - Traceback (most recent call last):
  File "/home/qodex/Gravity_core_export/gravity_core/wengine.py", line 78, in make_cps_connection
    self.cps.start()
  File "/home/qodex/.local/lib/python3.8/site-packages/portdatasplitter/main.py", line 37, in start
    self.create_server(self.server_ip, self.server_port)
  File "/home/qodex/.local/lib/python3.8/site-packages/portdatasplitter/main.py", line 61, in create_server
    self.serv.bind((ip, port))
OSError: [Errno 98] Address already in use

2021-05-05 12:09:47,944 - gravity_core.wlogger - ERROR - Traceback (most recent call last):
  File "/home/qodex/Gravity_core_export/gravity_core/wengine.py", line 78, in make_cps_connection
    self.cps.start()
  File "/home/qodex/.local/lib/python3.8/site-packages/portdatasplitter/main.py", line 37, in start
    self.create_server(self.server_ip, self.server_port)
  File "/home/qodex/.local/lib/python3.8/site-packages/portdatasplitter/main.py", line 61, in create_server
    self.serv.bind((ip, port))
OSError: [Errno 98] Address already in use

2021-05-05 12:09:52,953 - gravity_core.wlogger - ERROR - Traceback (most recent call last):
  File "/home/qodex/Gravity_core_export/gravity_core/wengine.py", line 78, in make_cps_connection
    self.cps.start()
  File "/home/qodex/.local/lib/python3.8/site-packages/portdatasplitter/main.py", line 37, in start
    self.create_server(self.server_ip, self.server_port)
  File "/home/qodex/.local/lib/python3.8/site-packages/portdatasplitter/main.py", line 61, in create_server
    self.serv.bind((ip, port))
OSError: [Errno 98] Address already in use

2021-05-05 12:09:57,961 - gravity_core.wlogger - ERROR - Traceback (most recent call last):
  File "/home/qodex/Gravity_core_export/gravity_core/wengine.py", line 78, in make_cps_connection
    self.cps.start()
  File "/home/qodex/.local/lib/python3.8/site-packages/portdatasplitter/main.py", line 37, in start
    self.create_server(self.server_ip, self.server_port)
  File "/home/qodex/.local/lib/python3.8/site-packages/portdatasplitter/main.py", line 61, in create_server
    self.serv.bind((ip, port))
OSError: [Errno 98] Address already in use

2021-05-05 12:09:59,187 - gravity_core.wlogger - ERROR - Traceback (most recent call last):
  File "/home/qodex/Gravity_core_export/gravity_core/wengine.py", line 78, in make_cps_connection
    self.cps.start()
  File "/home/qodex/.local/lib/python3.8/site-packages/portdatasplitter/main.py", line 37, in start
    self.create_server(self.server_ip, self.server_port)
  File "/home/qodex/.local/lib/python3.8/site-packages/portdatasplitter/main.py", line 61, in create_server
    self.serv.bind((ip, port))
OSError: [Errno 98] Address already in use

2021-05-05 15:45:48,159 - gravity_core.wlogger - ERROR - Ошибка в работе оператора!
2021-05-05 15:45:48,160 - gravity_core.wlogger - ERROR - Traceback (most recent call last):
  File "Gravity_core_export/wlauncher.py", line 54, in _start
    self.gravity_core.work()
  File "/home/qodex/Gravity_core_export/gravity_core/wengine.py", line 1213, in work
    self.operate_skud_stream()
  File "/home/qodex/Gravity_core_export/gravity_core/wengine.py", line 1169, in operate_skud_stream
    self.car_detect_operate(rfid, course)
  File "/home/qodex/Gravity_core_export/gravity_core/wengine.py", line 1058, in car_detect_operate
    self.operateCM(rfid, course, idtype)
  File "/home/qodex/Gravity_core_export/gravity_core/wengine.py", line 1075, in operateCM
    carnum = self.get_carnum_by_rfid(rfid)
  File "/home/qodex/Gravity_core_export/gravity_core/wengine.py", line 654, in get_carnum_by_rfid
    return carnum[0][0]
IndexError: list index out of range

2021-05-05 15:49:13,362 - gravity_core.wlogger - ERROR - Выход не зафиксирован фотоэлементом
2021-05-05 15:52:21,902 - gravity_core.wlogger - ERROR - Выход не зафиксирован фотоэлементом
2021-05-05 15:55:18,120 - gravity_core.wlogger - ERROR - Выход не зафиксирован фотоэлементом
2021-05-05 16:01:06,335 - gravity_core.wlogger - ERROR - Выход не зафиксирован фотоэлементом
2021-05-05 16:03:30,713 - gravity_core.wlogger - ERROR - Выход не зафиксирован фотоэлементом
2021-05-05 16:06:30,282 - gravity_core.wlogger - ERROR - Выход не зафиксирован фотоэлементом
2021-05-05 19:18:02,677 - gravity_core.wlogger - ERROR - Ошибка в работе оператора!
2021-05-05 19:18:02,678 - gravity_core.wlogger - ERROR - Traceback (most recent call last):
  File "/home/qodex/Gravity_core_export/wlauncher.py", line 54, in _start
    self.gravity_core.work()
  File "/home/qodex/Gravity_core_export/gravity_core/wengine.py", line 1213, in work
    self.operate_skud_stream()
  File "/home/qodex/Gravity_core_export/gravity_core/wengine.py", line 1169, in operate_skud_stream
    self.car_detect_operate(rfid, course)
  File "/home/qodex/Gravity_core_export/gravity_core/wengine.py", line 1058, in car_detect_operate
    self.operateCM(rfid, course, idtype)
  File "/home/qodex/Gravity_core_export/gravity_core/wengine.py", line 1075, in operateCM
    carnum = self.get_carnum_by_rfid(rfid)
  File "/home/qodex/Gravity_core_export/gravity_core/wengine.py", line 654, in get_carnum_by_rfid
    return carnum[0][0]
IndexError: list index out of range

2021-05-05 19:18:38,362 - gravity_core.wlogger - ERROR - Traceback (most recent call last):
  File "/home/qodex/Gravity_core_export/gravity_core/wlistener.py", line 102, in broadcastMsgSend
    conn.send(msg)
BrokenPipeError: [Errno 32] Broken pipe

2021-05-05 19:18:38,380 - gravity_core.wlogger - ERROR - Traceback (most recent call last):
  File "/home/qodex/Gravity_core_export/gravity_core/wlistener.py", line 102, in broadcastMsgSend
    conn.send(msg)
BrokenPipeError: [Errno 32] Broken pipe

2021-05-05 19:18:38,382 - gravity_core.wlogger - ERROR - Traceback (most recent call last):
  File "/home/qodex/Gravity_core_export/gravity_core/wlistener.py", line 102, in broadcastMsgSend
    conn.send(msg)
BrokenPipeError: [Errno 32] Broken pipe

2021-05-05 19:20:39,247 - gravity_core.wlogger - ERROR - Выход не зафиксирован фотоэлементом
2021-05-05 19:31:00,927 - gravity_core.wlogger - ERROR - Выход не зафиксирован фотоэлементом
2021-05-05 20:47:25,355 - gravity_core.wlogger - ERROR - Выход не зафиксирован фотоэлементом
2021-05-05 20:58:22,160 - gravity_core.wlogger - ERROR - Выход не зафиксирован фотоэлементом
2021-05-06 08:47:17,255 - gravity_core.wlogger - ERROR - Traceback (most recent call last):
  File "/home/qodex/Gravity_core_export/gravity_core/wlistener.py", line 102, in broadcastMsgSend
    conn.send(msg)
ConnectionResetError: [Errno 104] Connection reset by peer

2021-05-06 08:47:17,256 - gravity_core.wlogger - ERROR - Traceback (most recent call last):
  File "/home/qodex/Gravity_core_export/gravity_core/wlistener.py", line 102, in broadcastMsgSend
    conn.send(msg)
BrokenPipeError: [Errno 32] Broken pipe

2021-05-06 08:47:17,256 - gravity_core.wlogger - ERROR - Traceback (most recent call last):
  File "/home/qodex/Gravity_core_export/gravity_core/wlistener.py", line 102, in broadcastMsgSend
    conn.send(msg)
BrokenPipeError: [Errno 32] Broken pipe

2021-05-06 08:47:17,257 - gravity_core.wlogger - ERROR - Traceback (most recent call last):
  File "/home/qodex/Gravity_core_export/gravity_core/wlistener.py", line 102, in broadcastMsgSend
    conn.send(msg)
BrokenPipeError: [Errno 32] Broken pipe

2021-05-06 08:47:17,257 - gravity_core.wlogger - ERROR - Traceback (most recent call last):
  File "/home/qodex/Gravity_core_export/gravity_core/wlistener.py", line 102, in broadcastMsgSend
    conn.send(msg)
BrokenPipeError: [Errno 32] Broken pipe

2021-05-06 08:47:17,258 - gravity_core.wlogger - ERROR - Traceback (most recent call last):
  File "/home/qodex/Gravity_core_export/gravity_core/wlistener.py", line 102, in broadcastMsgSend
    conn.send(msg)
BrokenPipeError: [Errno 32] Broken pipe

2021-05-06 08:47:17,259 - gravity_core.wlogger - ERROR - Traceback (most recent call last):
  File "/home/qodex/Gravity_core_export/gravity_core/wlistener.py", line 102, in broadcastMsgSend
    conn.send(msg)
BrokenPipeError: [Errno 32] Broken pipe

2021-05-06 08:47:17,276 - gravity_core.wlogger - ERROR - Traceback (most recent call last):
  File "/home/qodex/Gravity_core_export/gravity_core/wlistener.py", line 102, in broadcastMsgSend
    conn.send(msg)
BrokenPipeError: [Errno 32] Broken pipe

2021-05-06 08:47:17,276 - gravity_core.wlogger - ERROR - Traceback (most recent call last):
  File "/home/qodex/Gravity_core_export/gravity_core/wlistener.py", line 102, in broadcastMsgSend
    conn.send(msg)
BrokenPipeError: [Errno 32] Broken pipe

2021-05-06 08:47:17,277 - gravity_core.wlogger - ERROR - Traceback (most recent call last):
  File "/home/qodex/Gravity_core_export/gravity_core/wlistener.py", line 102, in broadcastMsgSend
    conn.send(msg)
BrokenPipeError: [Errno 32] Broken pipe

2021-05-06 08:47:17,277 - gravity_core.wlogger - ERROR - Traceback (most recent call last):
  File "/home/qodex/Gravity_core_export/gravity_core/wlistener.py", line 102, in broadcastMsgSend
    conn.send(msg)
BrokenPipeError: [Errno 32] Broken pipe

2021-05-06 08:47:17,278 - gravity_core.wlogger - ERROR - Traceback (most recent call last):
  File "/home/qodex/Gravity_core_export/gravity_core/wlistener.py", line 102, in broadcastMsgSend
    conn.send(msg)
BrokenPipeError: [Errno 32] Broken pipe

2021-05-06 08:47:17,279 - gravity_core.wlogger - ERROR - Traceback (most recent call last):
  File "/home/qodex/Gravity_core_export/gravity_core/wlistener.py", line 102, in broadcastMsgSend
    conn.send(msg)
BrokenPipeError: [Errno 32] Broken pipe

2021-05-06 08:47:17,279 - gravity_core.wlogger - ERROR - Traceback (most recent call last):
  File "/home/qodex/Gravity_core_export/gravity_core/wlistener.py", line 102, in broadcastMsgSend
    conn.send(msg)
BrokenPipeError: [Errno 32] Broken pipe

2021-05-06 08:47:17,280 - gravity_core.wlogger - ERROR - Traceback (most recent call last):
  File "/home/qodex/Gravity_core_export/gravity_core/wlistener.py", line 102, in broadcastMsgSend
    conn.send(msg)
BrokenPipeError: [Errno 32] Broken pipe

2021-05-06 08:47:17,280 - gravity_core.wlogger - ERROR - Traceback (most recent call last):
  File "/home/qodex/Gravity_core_export/gravity_core/wlistener.py", line 102, in broadcastMsgSend
    conn.send(msg)
BrokenPipeError: [Errno 32] Broken pipe

2021-05-06 08:47:17,281 - gravity_core.wlogger - ERROR - Traceback (most recent call last):
  File "/home/qodex/Gravity_core_export/gravity_core/wlistener.py", line 102, in broadcastMsgSend
    conn.send(msg)
BrokenPipeError: [Errno 32] Broken pipe

2021-05-06 08:47:17,282 - gravity_core.wlogger - ERROR - Traceback (most recent call last):
  File "/home/qodex/Gravity_core_export/gravity_core/wlistener.py", line 102, in broadcastMsgSend
    conn.send(msg)
BrokenPipeError: [Errno 32] Broken pipe

2021-05-06 08:47:17,283 - gravity_core.wlogger - ERROR - Traceback (most recent call last):
  File "/home/qodex/Gravity_core_export/gravity_core/wlistener.py", line 102, in broadcastMsgSend
    conn.send(msg)
BrokenPipeError: [Errno 32] Broken pipe

2021-05-06 08:47:17,283 - gravity_core.wlogger - ERROR - Traceback (most recent call last):
  File "/home/qodex/Gravity_core_export/gravity_core/wlistener.py", line 102, in broadcastMsgSend
    conn.send(msg)
BrokenPipeError: [Errno 32] Broken pipe

2021-05-06 08:47:18,279 - gravity_core.wlogger - ERROR - Traceback (most recent call last):
  File "/home/qodex/Gravity_core_export/gravity_core/wlistener.py", line 102, in broadcastMsgSend
    conn.send(msg)
BrokenPipeError: [Errno 32] Broken pipe

2021-05-06 08:49:18,212 - gravity_core.wlogger - ERROR - Выход не зафиксирован фотоэлементом
2021-05-06 08:51:36,587 - gravity_core.wlogger - ERROR - Выход не зафиксирован фотоэлементом
2021-05-06 10:33:20,000 - gravity_core.wlogger - ERROR - Traceback (most recent call last):
  File "/home/qodex/Gravity_core_export/gravity_core/wlistener.py", line 102, in broadcastMsgSend
    conn.send(msg)
BrokenPipeError: [Errno 32] Broken pipe

2021-05-06 10:33:20,001 - gravity_core.wlogger - ERROR - Traceback (most recent call last):
  File "/home/qodex/Gravity_core_export/gravity_core/wlistener.py", line 102, in broadcastMsgSend
    conn.send(msg)
BrokenPipeError: [Errno 32] Broken pipe

2021-05-06 10:33:20,002 - gravity_core.wlogger - ERROR - Traceback (most recent call last):
  File "/home/qodex/Gravity_core_export/gravity_core/wlistener.py", line 102, in broadcastMsgSend
    conn.send(msg)
BrokenPipeError: [Errno 32] Broken pipe

2021-05-06 10:33:23,113 - gravity_core.wlogger - ERROR - Traceback (most recent call last):
  File "/home/qodex/Gravity_core_export/gravity_core/wlistener.py", line 102, in broadcastMsgSend
    conn.send(msg)
BrokenPipeError: [Errno 32] Broken pipe

2021-05-06 10:33:23,114 - gravity_core.wlogger - ERROR - Traceback (most recent call last):
  File "/home/qodex/Gravity_core_export/gravity_core/wlistener.py", line 102, in broadcastMsgSend
    conn.send(msg)
BrokenPipeError: [Errno 32] Broken pipe

2021-05-06 10:33:23,115 - gravity_core.wlogger - ERROR - Traceback (most recent call last):
  File "/home/qodex/Gravity_core_export/gravity_core/wlistener.py", line 102, in broadcastMsgSend
    conn.send(msg)
BrokenPipeError: [Errno 32] Broken pipe

2021-05-06 10:34:04,716 - gravity_core.wlogger - ERROR - Traceback (most recent call last):
  File "/home/qodex/Gravity_core_export/gravity_core/wlistener.py", line 102, in broadcastMsgSend
    conn.send(msg)
BrokenPipeError: [Errno 32] Broken pipe

2021-05-06 10:34:04,717 - gravity_core.wlogger - ERROR - Traceback (most recent call last):
  File "/home/qodex/Gravity_core_export/gravity_core/wlistener.py", line 102, in broadcastMsgSend
    conn.send(msg)
BrokenPipeError: [Errno 32] Broken pipe

2021-05-06 10:34:04,717 - gravity_core.wlogger - ERROR - Traceback (most recent call last):
  File "/home/qodex/Gravity_core_export/gravity_core/wlistener.py", line 102, in broadcastMsgSend
    conn.send(msg)
BrokenPipeError: [Errno 32] Broken pipe

2021-05-06 10:55:11,634 - gravity_core.wlogger - ERROR - Traceback (most recent call last):
  File "/home/qodex/Gravity_core_export/gravity_core/wlistener.py", line 102, in broadcastMsgSend
    conn.send(msg)
BrokenPipeError: [Errno 32] Broken pipe

2021-05-06 10:55:13,796 - gravity_core.wlogger - ERROR - Traceback (most recent call last):
  File "/home/qodex/Gravity_core_export/gravity_core/wlistener.py", line 102, in broadcastMsgSend
    conn.send(msg)
BrokenPipeError: [Errno 32] Broken pipe

2021-05-06 10:55:36,076 - gravity_core.wlogger - ERROR - Traceback (most recent call last):
  File "/home/qodex/Gravity_core_export/gravity_core/wlistener.py", line 102, in broadcastMsgSend
    conn.send(msg)
BrokenPipeError: [Errno 32] Broken pipe

2021-05-06 12:15:20,140 - gravity_core.wlogger - ERROR - Traceback (most recent call last):
  File "/home/qodex/Gravity_core_export/gravity_core/wlistener.py", line 102, in broadcastMsgSend
    conn.send(msg)
BrokenPipeError: [Errno 32] Broken pipe

2021-05-06 12:15:21,149 - gravity_core.wlogger - ERROR - Traceback (most recent call last):
  File "/home/qodex/Gravity_core_export/gravity_core/wlistener.py", line 102, in broadcastMsgSend
    conn.send(msg)
BrokenPipeError: [Errno 32] Broken pipe

2021-05-06 12:15:26,669 - gravity_core.wlogger - ERROR - Traceback (most recent call last):
  File "/home/qodex/Gravity_core_export/gravity_core/wlistener.py", line 102, in broadcastMsgSend
    conn.send(msg)
BrokenPipeError: [Errno 32] Broken pipe

2021-05-06 12:34:28,151 - gravity_core.wlogger - ERROR - Traceback (most recent call last):
  File "/home/qodex/Gravity_core_export/gravity_core/wlistener.py", line 102, in broadcastMsgSend
    conn.send(msg)
BrokenPipeError: [Errno 32] Broken pipe

2021-05-06 12:34:29,657 - gravity_core.wlogger - ERROR - Traceback (most recent call last):
  File "/home/qodex/Gravity_core_export/gravity_core/wlistener.py", line 102, in broadcastMsgSend
    conn.send(msg)
BrokenPipeError: [Errno 32] Broken pipe

2021-05-06 12:34:31,159 - gravity_core.wlogger - ERROR - Traceback (most recent call last):
  File "/home/qodex/Gravity_core_export/gravity_core/wlistener.py", line 102, in broadcastMsgSend
    conn.send(msg)
BrokenPipeError: [Errno 32] Broken pipe

2021-05-06 15:42:46,203 - gravity_core.wlogger - ERROR - Traceback (most recent call last):
  File "/home/qodex/Gravity_core_export/gravity_core/wlistener.py", line 102, in broadcastMsgSend
    conn.send(msg)
BrokenPipeError: [Errno 32] Broken pipe

2021-05-06 15:42:50,197 - gravity_core.wlogger - ERROR - Traceback (most recent call last):
  File "/home/qodex/Gravity_core_export/gravity_core/wlistener.py", line 102, in broadcastMsgSend
    conn.send(msg)
BrokenPipeError: [Errno 32] Broken pipe

2021-05-06 15:42:50,249 - gravity_core.wlogger - ERROR - Traceback (most recent call last):
  File "/home/qodex/Gravity_core_export/gravity_core/wlistener.py", line 102, in broadcastMsgSend
    conn.send(msg)
BrokenPipeError: [Errno 32] Broken pipe

2021-05-06 15:56:29,387 - gravity_core.wlogger - ERROR - Traceback (most recent call last):
  File "/home/qodex/Gravity_core_export/gravity_core/wengine.py", line 723, in send_act
    sig_funcs.send_json_reports(self.sqlshell, wclient, self.poligon_id,
  File "/home/qodex/Gravity_core_export/gravity_core/reports/signall_reports_funcs.py", line 88, in send_json_reports
    wclient.send_file(filename)
AttributeError: 'str' object has no attribute 'send_file'

2021-05-06 15:56:29,439 - gravity_core.wlogger - ERROR - Traceback (most recent call last):
  File "/home/qodex/Gravity_core_export/gravity_core/wengine.py", line 723, in send_act
    sig_funcs.send_json_reports(self.sqlshell, wclient, self.poligon_id,
  File "/home/qodex/Gravity_core_export/gravity_core/reports/signall_reports_funcs.py", line 88, in send_json_reports
    wclient.send_file(filename)
AttributeError: 'str' object has no attribute 'send_file'

2021-05-06 16:00:29,365 - gravity_core.wlogger - ERROR - Traceback (most recent call last):
  File "/home/qodex/Gravity_core_export/gravity_core/wengine.py", line 723, in send_act
    sig_funcs.send_json_reports(self.sqlshell, wclient, self.poligon_id,
  File "/home/qodex/Gravity_core_export/gravity_core/reports/signall_reports_funcs.py", line 88, in send_json_reports
    wclient.send_file(filename)
AttributeError: 'str' object has no attribute 'send_file'

2021-05-06 16:00:29,419 - gravity_core.wlogger - ERROR - Traceback (most recent call last):
  File "/home/qodex/Gravity_core_export/gravity_core/wengine.py", line 723, in send_act
    sig_funcs.send_json_reports(self.sqlshell, wclient, self.poligon_id,
  File "/home/qodex/Gravity_core_export/gravity_core/reports/signall_reports_funcs.py", line 88, in send_json_reports
    wclient.send_file(filename)
AttributeError: 'str' object has no attribute 'send_file'

2021-05-06 16:11:42,657 - gravity_core.wlogger - ERROR - Traceback (most recent call last):
  File "/home/qodex/Gravity_core_export/gravity_core/wengine.py", line 723, in send_act
    sig_funcs.send_json_reports(self.sqlshell, wclient, self.poligon_id,
  File "/home/qodex/Gravity_core_export/gravity_core/reports/signall_reports_funcs.py", line 88, in send_json_reports
    wclient.send_file(filename)
AttributeError: 'str' object has no attribute 'send_file'

2021-05-06 16:11:42,713 - gravity_core.wlogger - ERROR - Traceback (most recent call last):
  File "/home/qodex/Gravity_core_export/gravity_core/wengine.py", line 723, in send_act
    sig_funcs.send_json_reports(self.sqlshell, wclient, self.poligon_id,
  File "/home/qodex/Gravity_core_export/gravity_core/reports/signall_reports_funcs.py", line 88, in send_json_reports
    wclient.send_file(filename)
AttributeError: 'str' object has no attribute 'send_file'

2021-05-06 16:24:15,534 - gravity_core.wlogger - ERROR - Traceback (most recent call last):
  File "/home/qodex/Gravity_core_export/gravity_core/wengine.py", line 723, in send_act
    sig_funcs.send_json_reports(self.sqlshell, wclient, self.poligon_id,
  File "/home/qodex/Gravity_core_export/gravity_core/reports/signall_reports_funcs.py", line 88, in send_json_reports
    wclient.send_file(filename)
AttributeError: 'str' object has no attribute 'send_file'

2021-05-06 16:24:15,585 - gravity_core.wlogger - ERROR - Traceback (most recent call last):
  File "/home/qodex/Gravity_core_export/gravity_core/wengine.py", line 723, in send_act
    sig_funcs.send_json_reports(self.sqlshell, wclient, self.poligon_id,
  File "/home/qodex/Gravity_core_export/gravity_core/reports/signall_reports_funcs.py", line 88, in send_json_reports
    wclient.send_file(filename)
AttributeError: 'str' object has no attribute 'send_file'

2021-05-06 16:43:33,687 - gravity_core.wlogger - ERROR - Traceback (most recent call last):
  File "/home/qodex/Gravity_core_export/gravity_core/wlistener.py", line 102, in broadcastMsgSend
    conn.send(msg)
BrokenPipeError: [Errno 32] Broken pipe

2021-05-06 16:43:39,184 - gravity_core.wlogger - ERROR - Traceback (most recent call last):
  File "/home/qodex/Gravity_core_export/gravity_core/wlistener.py", line 102, in broadcastMsgSend
    conn.send(msg)
BrokenPipeError: [Errno 32] Broken pipe

2021-05-06 16:43:44,683 - gravity_core.wlogger - ERROR - Traceback (most recent call last):
  File "/home/qodex/Gravity_core_export/gravity_core/wlistener.py", line 102, in broadcastMsgSend
    conn.send(msg)
BrokenPipeError: [Errno 32] Broken pipe

2021-05-06 16:45:12,416 - gravity_core.wlogger - ERROR - Traceback (most recent call last):
  File "/home/qodex/Gravity_core_export/gravity_core/wengine.py", line 723, in send_act
    sig_funcs.send_json_reports(self.sqlshell, wclient, self.poligon_id,
  File "/home/qodex/Gravity_core_export/gravity_core/reports/signall_reports_funcs.py", line 88, in send_json_reports
    wclient.send_file(filename)
AttributeError: 'str' object has no attribute 'send_file'

2021-05-06 16:45:12,471 - gravity_core.wlogger - ERROR - Traceback (most recent call last):
  File "/home/qodex/Gravity_core_export/gravity_core/wengine.py", line 723, in send_act
    sig_funcs.send_json_reports(self.sqlshell, wclient, self.poligon_id,
  File "/home/qodex/Gravity_core_export/gravity_core/reports/signall_reports_funcs.py", line 88, in send_json_reports
    wclient.send_file(filename)
AttributeError: 'str' object has no attribute 'send_file'

2021-05-06 16:48:58,544 - gravity_core.wlogger - ERROR - Traceback (most recent call last):
  File "/home/qodex/Gravity_core_export/gravity_core/wengine.py", line 723, in send_act
    sig_funcs.send_json_reports(self.sqlshell, wclient, self.poligon_id,
  File "/home/qodex/Gravity_core_export/gravity_core/reports/signall_reports_funcs.py", line 88, in send_json_reports
    wclient.send_file(filename)
AttributeError: 'str' object has no attribute 'send_file'

2021-05-06 16:48:58,596 - gravity_core.wlogger - ERROR - Traceback (most recent call last):
  File "/home/qodex/Gravity_core_export/gravity_core/wengine.py", line 723, in send_act
    sig_funcs.send_json_reports(self.sqlshell, wclient, self.poligon_id,
  File "/home/qodex/Gravity_core_export/gravity_core/reports/signall_reports_funcs.py", line 88, in send_json_reports
    wclient.send_file(filename)
AttributeError: 'str' object has no attribute 'send_file'

2021-05-06 17:32:36,188 - gravity_core.wlogger - ERROR - Traceback (most recent call last):
  File "/home/qodex/Gravity_core_export/gravity_core/wengine.py", line 723, in send_act
    sig_funcs.send_json_reports(self.sqlshell, wclient, self.poligon_id,
  File "/home/qodex/Gravity_core_export/gravity_core/reports/signall_reports_funcs.py", line 88, in send_json_reports
    wclient.send_file(filename)
AttributeError: 'str' object has no attribute 'send_file'

2021-05-06 17:32:36,240 - gravity_core.wlogger - ERROR - Traceback (most recent call last):
  File "/home/qodex/Gravity_core_export/gravity_core/wengine.py", line 723, in send_act
    sig_funcs.send_json_reports(self.sqlshell, wclient, self.poligon_id,
  File "/home/qodex/Gravity_core_export/gravity_core/reports/signall_reports_funcs.py", line 88, in send_json_reports
    wclient.send_file(filename)
AttributeError: 'str' object has no attribute 'send_file'

2021-05-06 17:42:06,833 - gravity_core.wlogger - ERROR - Traceback (most recent call last):
  File "/home/qodex/Gravity_core_export/gravity_core/wengine.py", line 723, in send_act
    sig_funcs.send_json_reports(self.sqlshell, wclient, self.poligon_id,
  File "/home/qodex/Gravity_core_export/gravity_core/reports/signall_reports_funcs.py", line 88, in send_json_reports
    wclient.send_file(filename)
AttributeError: 'str' object has no attribute 'send_file'

2021-05-06 17:42:06,882 - gravity_core.wlogger - ERROR - Traceback (most recent call last):
  File "/home/qodex/Gravity_core_export/gravity_core/wengine.py", line 723, in send_act
    sig_funcs.send_json_reports(self.sqlshell, wclient, self.poligon_id,
  File "/home/qodex/Gravity_core_export/gravity_core/reports/signall_reports_funcs.py", line 88, in send_json_reports
    wclient.send_file(filename)
AttributeError: 'str' object has no attribute 'send_file'

2021-05-06 17:48:42,150 - gravity_core.wlogger - ERROR - Ошибка в работе оператора!
2021-05-06 17:48:42,151 - gravity_core.wlogger - ERROR - Traceback (most recent call last):
  File "Gravity_core_export/wlauncher.py", line 54, in _start
    self.gravity_core.work()
  File "/home/qodex/Gravity_core_export/gravity_core/wengine.py", line 1215, in work
    self.operate_skud_stream()
  File "/home/qodex/Gravity_core_export/gravity_core/wengine.py", line 1171, in operate_skud_stream
    self.car_detect_operate(rfid, course)
  File "/home/qodex/Gravity_core_export/gravity_core/wengine.py", line 1060, in car_detect_operate
    self.operateCM(rfid, course, idtype)
  File "/home/qodex/Gravity_core_export/gravity_core/wengine.py", line 1077, in operateCM
    carnum = self.get_carnum_by_rfid(rfid)
  File "/home/qodex/Gravity_core_export/gravity_core/wengine.py", line 654, in get_carnum_by_rfid
    return carnum[0][0]
IndexError: list index out of range

2021-05-06 19:12:06,709 - gravity_core.wlogger - ERROR - Traceback (most recent call last):
  File "/home/qodex/Gravity_core_export/gravity_core/wlistener.py", line 102, in broadcastMsgSend
    conn.send(msg)
BrokenPipeError: [Errno 32] Broken pipe

2021-05-06 19:12:07,711 - gravity_core.wlogger - ERROR - Traceback (most recent call last):
  File "/home/qodex/Gravity_core_export/gravity_core/wlistener.py", line 102, in broadcastMsgSend
    conn.send(msg)
BrokenPipeError: [Errno 32] Broken pipe

2021-05-06 19:12:09,216 - gravity_core.wlogger - ERROR - Traceback (most recent call last):
  File "/home/qodex/Gravity_core_export/gravity_core/wlistener.py", line 102, in broadcastMsgSend
    conn.send(msg)
BrokenPipeError: [Errno 32] Broken pipe

2021-05-06 21:26:33,623 - gravity_core.wlogger - ERROR - Traceback (most recent call last):
  File "/home/qodex/Gravity_core_export/gravity_core/wlistener.py", line 102, in broadcastMsgSend
    conn.send(msg)
BrokenPipeError: [Errno 32] Broken pipe

2021-05-06 21:26:43,400 - gravity_core.wlogger - ERROR - Traceback (most recent call last):
  File "/home/qodex/Gravity_core_export/gravity_core/wlistener.py", line 102, in broadcastMsgSend
    conn.send(msg)
BrokenPipeError: [Errno 32] Broken pipe

2021-05-06 21:27:00,017 - gravity_core.wlogger - ERROR - Traceback (most recent call last):
  File "/home/qodex/Gravity_core_export/gravity_core/wlistener.py", line 102, in broadcastMsgSend
    conn.send(msg)
BrokenPipeError: [Errno 32] Broken pipe

2021-05-07 11:14:37,214 - gravity_core.wlogger - ERROR - Traceback (most recent call last):
  File "/home/qodex/Gravity_core_export/gravity_core/wengine.py", line 723, in send_act
    sig_funcs.send_json_reports(self.sqlshell, wclient, self.poligon_id,
  File "/home/qodex/Gravity_core_export/gravity_core/reports/signall_reports_funcs.py", line 88, in send_json_reports
    wclient.send_file(filename)
AttributeError: 'str' object has no attribute 'send_file'

2021-05-07 11:14:37,267 - gravity_core.wlogger - ERROR - Traceback (most recent call last):
  File "/home/qodex/Gravity_core_export/gravity_core/wengine.py", line 723, in send_act
    sig_funcs.send_json_reports(self.sqlshell, wclient, self.poligon_id,
  File "/home/qodex/Gravity_core_export/gravity_core/reports/signall_reports_funcs.py", line 88, in send_json_reports
    wclient.send_file(filename)
AttributeError: 'str' object has no attribute 'send_file'

2021-05-07 11:20:38,973 - gravity_core.wlogger - ERROR - Traceback (most recent call last):
  File "/home/qodex/Gravity_core_export/gravity_core/wengine.py", line 723, in send_act
    sig_funcs.send_json_reports(self.sqlshell, wclient, self.poligon_id,
  File "/home/qodex/Gravity_core_export/gravity_core/reports/signall_reports_funcs.py", line 88, in send_json_reports
    wclient.send_file(filename)
AttributeError: 'str' object has no attribute 'send_file'

2021-05-07 11:20:39,028 - gravity_core.wlogger - ERROR - Traceback (most recent call last):
  File "/home/qodex/Gravity_core_export/gravity_core/wengine.py", line 723, in send_act
    sig_funcs.send_json_reports(self.sqlshell, wclient, self.poligon_id,
  File "/home/qodex/Gravity_core_export/gravity_core/reports/signall_reports_funcs.py", line 88, in send_json_reports
    wclient.send_file(filename)
AttributeError: 'str' object has no attribute 'send_file'

2021-05-07 11:56:47,115 - gravity_core.wlogger - ERROR - Traceback (most recent call last):
  File "/home/qodex/Gravity_core_export/gravity_core/wengine.py", line 723, in send_act
    sig_funcs.send_json_reports(self.sqlshell, wclient, self.poligon_id,
  File "/home/qodex/Gravity_core_export/gravity_core/reports/signall_reports_funcs.py", line 88, in send_json_reports
    wclient.send_file(filename)
AttributeError: 'str' object has no attribute 'send_file'

2021-05-07 11:56:47,172 - gravity_core.wlogger - ERROR - Traceback (most recent call last):
  File "/home/qodex/Gravity_core_export/gravity_core/wengine.py", line 723, in send_act
    sig_funcs.send_json_reports(self.sqlshell, wclient, self.poligon_id,
  File "/home/qodex/Gravity_core_export/gravity_core/reports/signall_reports_funcs.py", line 88, in send_json_reports
    wclient.send_file(filename)
AttributeError: 'str' object has no attribute 'send_file'

2021-05-07 13:09:43,159 - gravity_core.wlogger - ERROR - Traceback (most recent call last):
  File "/home/qodex/Gravity_core_export/gravity_core/wlistener.py", line 102, in broadcastMsgSend
    conn.send(msg)
BrokenPipeError: [Errno 32] Broken pipe

2021-05-07 13:14:33,702 - gravity_core.wlogger - ERROR - Traceback (most recent call last):
  File "/home/qodex/Gravity_core_export/gravity_core/wlistener.py", line 102, in broadcastMsgSend
    conn.send(msg)
BrokenPipeError: [Errno 32] Broken pipe

2021-05-07 13:14:38,259 - gravity_core.wlogger - ERROR - Traceback (most recent call last):
  File "/home/qodex/Gravity_core_export/gravity_core/wlistener.py", line 102, in broadcastMsgSend
    conn.send(msg)
BrokenPipeError: [Errno 32] Broken pipe

2021-05-07 13:15:42,303 - gravity_core.wlogger - ERROR - Traceback (most recent call last):
  File "/home/qodex/Gravity_core_export/gravity_core/wengine.py", line 723, in send_act
    sig_funcs.send_json_reports(self.sqlshell, wclient, self.poligon_id,
  File "/home/qodex/Gravity_core_export/gravity_core/reports/signall_reports_funcs.py", line 88, in send_json_reports
    wclient.send_file(filename)
AttributeError: 'str' object has no attribute 'send_file'

2021-05-07 13:15:42,359 - gravity_core.wlogger - ERROR - Traceback (most recent call last):
  File "/home/qodex/Gravity_core_export/gravity_core/wengine.py", line 723, in send_act
    sig_funcs.send_json_reports(self.sqlshell, wclient, self.poligon_id,
  File "/home/qodex/Gravity_core_export/gravity_core/reports/signall_reports_funcs.py", line 88, in send_json_reports
    wclient.send_file(filename)
AttributeError: 'str' object has no attribute 'send_file'

2021-05-07 13:23:19,090 - gravity_core.wlogger - ERROR - Traceback (most recent call last):
  File "/home/qodex/Gravity_core_export/gravity_core/wengine.py", line 723, in send_act
    sig_funcs.send_json_reports(self.sqlshell, wclient, self.poligon_id,
  File "/home/qodex/Gravity_core_export/gravity_core/reports/signall_reports_funcs.py", line 88, in send_json_reports
    wclient.send_file(filename)
AttributeError: 'str' object has no attribute 'send_file'

2021-05-07 13:23:19,146 - gravity_core.wlogger - ERROR - Traceback (most recent call last):
  File "/home/qodex/Gravity_core_export/gravity_core/wengine.py", line 723, in send_act
    sig_funcs.send_json_reports(self.sqlshell, wclient, self.poligon_id,
  File "/home/qodex/Gravity_core_export/gravity_core/reports/signall_reports_funcs.py", line 88, in send_json_reports
    wclient.send_file(filename)
AttributeError: 'str' object has no attribute 'send_file'

2021-05-07 13:29:30,895 - gravity_core.wlogger - ERROR - Traceback (most recent call last):
  File "/home/qodex/Gravity_core_export/gravity_core/wengine.py", line 723, in send_act
    sig_funcs.send_json_reports(self.sqlshell, wclient, self.poligon_id,
  File "/home/qodex/Gravity_core_export/gravity_core/reports/signall_reports_funcs.py", line 88, in send_json_reports
    wclient.send_file(filename)
AttributeError: 'str' object has no attribute 'send_file'

2021-05-07 13:29:30,948 - gravity_core.wlogger - ERROR - Traceback (most recent call last):
  File "/home/qodex/Gravity_core_export/gravity_core/wengine.py", line 723, in send_act
    sig_funcs.send_json_reports(self.sqlshell, wclient, self.poligon_id,
  File "/home/qodex/Gravity_core_export/gravity_core/reports/signall_reports_funcs.py", line 88, in send_json_reports
    wclient.send_file(filename)
AttributeError: 'str' object has no attribute 'send_file'

2021-05-07 14:28:24,581 - gravity_core.wlogger - ERROR - Traceback (most recent call last):
  File "/home/qodex/Gravity_core_export/gravity_core/wengine.py", line 723, in send_act
    sig_funcs.send_json_reports(self.sqlshell, wclient, self.poligon_id,
  File "/home/qodex/Gravity_core_export/gravity_core/reports/signall_reports_funcs.py", line 88, in send_json_reports
    wclient.send_file(filename)
AttributeError: 'str' object has no attribute 'send_file'

2021-05-07 14:28:24,633 - gravity_core.wlogger - ERROR - Traceback (most recent call last):
  File "/home/qodex/Gravity_core_export/gravity_core/wengine.py", line 723, in send_act
    sig_funcs.send_json_reports(self.sqlshell, wclient, self.poligon_id,
  File "/home/qodex/Gravity_core_export/gravity_core/reports/signall_reports_funcs.py", line 88, in send_json_reports
    wclient.send_file(filename)
AttributeError: 'str' object has no attribute 'send_file'

2021-05-07 14:30:46,368 - gravity_core.wlogger - ERROR - Traceback (most recent call last):
  File "/home/qodex/Gravity_core_export/gravity_core/wengine.py", line 723, in send_act
    sig_funcs.send_json_reports(self.sqlshell, wclient, self.poligon_id,
  File "/home/qodex/Gravity_core_export/gravity_core/reports/signall_reports_funcs.py", line 88, in send_json_reports
    wclient.send_file(filename)
AttributeError: 'str' object has no attribute 'send_file'

2021-05-07 14:30:46,421 - gravity_core.wlogger - ERROR - Traceback (most recent call last):
  File "/home/qodex/Gravity_core_export/gravity_core/wengine.py", line 723, in send_act
    sig_funcs.send_json_reports(self.sqlshell, wclient, self.poligon_id,
  File "/home/qodex/Gravity_core_export/gravity_core/reports/signall_reports_funcs.py", line 88, in send_json_reports
    wclient.send_file(filename)
AttributeError: 'str' object has no attribute 'send_file'

2021-05-07 14:34:14,449 - gravity_core.wlogger - ERROR - Traceback (most recent call last):
  File "/home/qodex/Gravity_core_export/gravity_core/wengine.py", line 723, in send_act
    sig_funcs.send_json_reports(self.sqlshell, wclient, self.poligon_id,
  File "/home/qodex/Gravity_core_export/gravity_core/reports/signall_reports_funcs.py", line 88, in send_json_reports
    wclient.send_file(filename)
AttributeError: 'str' object has no attribute 'send_file'

2021-05-07 14:34:14,502 - gravity_core.wlogger - ERROR - Traceback (most recent call last):
  File "/home/qodex/Gravity_core_export/gravity_core/wengine.py", line 723, in send_act
    sig_funcs.send_json_reports(self.sqlshell, wclient, self.poligon_id,
  File "/home/qodex/Gravity_core_export/gravity_core/reports/signall_reports_funcs.py", line 88, in send_json_reports
    wclient.send_file(filename)
AttributeError: 'str' object has no attribute 'send_file'

2021-05-07 15:04:05,587 - gravity_core.wlogger - ERROR - Traceback (most recent call last):
  File "/home/qodex/Gravity_core_export/gravity_core/wengine.py", line 723, in send_act
    sig_funcs.send_json_reports(self.sqlshell, wclient, self.poligon_id,
  File "/home/qodex/Gravity_core_export/gravity_core/reports/signall_reports_funcs.py", line 88, in send_json_reports
    wclient.send_file(filename)
AttributeError: 'str' object has no attribute 'send_file'

2021-05-07 15:04:05,636 - gravity_core.wlogger - ERROR - Traceback (most recent call last):
  File "/home/qodex/Gravity_core_export/gravity_core/wengine.py", line 723, in send_act
    sig_funcs.send_json_reports(self.sqlshell, wclient, self.poligon_id,
  File "/home/qodex/Gravity_core_export/gravity_core/reports/signall_reports_funcs.py", line 88, in send_json_reports
    wclient.send_file(filename)
AttributeError: 'str' object has no attribute 'send_file'

2021-05-07 15:10:47,015 - gravity_core.wlogger - ERROR - Traceback (most recent call last):
  File "/home/qodex/Gravity_core_export/gravity_core/wengine.py", line 723, in send_act
    sig_funcs.send_json_reports(self.sqlshell, wclient, self.poligon_id,
  File "/home/qodex/Gravity_core_export/gravity_core/reports/signall_reports_funcs.py", line 88, in send_json_reports
    wclient.send_file(filename)
AttributeError: 'str' object has no attribute 'send_file'

2021-05-07 15:10:47,065 - gravity_core.wlogger - ERROR - Traceback (most recent call last):
  File "/home/qodex/Gravity_core_export/gravity_core/wengine.py", line 723, in send_act
    sig_funcs.send_json_reports(self.sqlshell, wclient, self.poligon_id,
  File "/home/qodex/Gravity_core_export/gravity_core/reports/signall_reports_funcs.py", line 88, in send_json_reports
    wclient.send_file(filename)
AttributeError: 'str' object has no attribute 'send_file'

2021-05-07 15:15:47,809 - gravity_core.wlogger - ERROR - Traceback (most recent call last):
  File "/home/qodex/Gravity_core_export/gravity_core/wlistener.py", line 102, in broadcastMsgSend
    conn.send(msg)
BrokenPipeError: [Errno 32] Broken pipe

2021-05-07 15:15:47,811 - gravity_core.wlogger - ERROR - Traceback (most recent call last):
  File "/home/qodex/Gravity_core_export/gravity_core/wlistener.py", line 102, in broadcastMsgSend
    conn.send(msg)
BrokenPipeError: [Errno 32] Broken pipe

2021-05-07 15:15:47,858 - gravity_core.wlogger - ERROR - Traceback (most recent call last):
  File "/home/qodex/Gravity_core_export/gravity_core/wlistener.py", line 102, in broadcastMsgSend
    conn.send(msg)
BrokenPipeError: [Errno 32] Broken pipe

2021-05-07 15:15:47,858 - gravity_core.wlogger - ERROR - Traceback (most recent call last):
  File "/home/qodex/Gravity_core_export/gravity_core/wlistener.py", line 102, in broadcastMsgSend
    conn.send(msg)
BrokenPipeError: [Errno 32] Broken pipe

2021-05-07 15:15:47,876 - gravity_core.wlogger - ERROR - Traceback (most recent call last):
  File "/home/qodex/Gravity_core_export/gravity_core/wlistener.py", line 102, in broadcastMsgSend
    conn.send(msg)
BrokenPipeError: [Errno 32] Broken pipe

2021-05-07 15:15:47,877 - gravity_core.wlogger - ERROR - Traceback (most recent call last):
  File "/home/qodex/Gravity_core_export/gravity_core/wlistener.py", line 102, in broadcastMsgSend
    conn.send(msg)
BrokenPipeError: [Errno 32] Broken pipe

2021-05-07 15:16:41,802 - gravity_core.wlogger - ERROR - Traceback (most recent call last):
  File "/home/qodex/Gravity_core_export/gravity_core/wengine.py", line 723, in send_act
    sig_funcs.send_json_reports(self.sqlshell, wclient, self.poligon_id,
  File "/home/qodex/Gravity_core_export/gravity_core/reports/signall_reports_funcs.py", line 88, in send_json_reports
    wclient.send_file(filename)
AttributeError: 'str' object has no attribute 'send_file'

2021-05-07 15:16:41,853 - gravity_core.wlogger - ERROR - Traceback (most recent call last):
  File "/home/qodex/Gravity_core_export/gravity_core/wengine.py", line 723, in send_act
    sig_funcs.send_json_reports(self.sqlshell, wclient, self.poligon_id,
  File "/home/qodex/Gravity_core_export/gravity_core/reports/signall_reports_funcs.py", line 88, in send_json_reports
    wclient.send_file(filename)
AttributeError: 'str' object has no attribute 'send_file'

2021-05-07 16:40:10,931 - gravity_core.wlogger - ERROR - Traceback (most recent call last):
  File "/home/qodex/Gravity_core_export/gravity_core/wlistener.py", line 102, in broadcastMsgSend
    conn.send(msg)
BrokenPipeError: [Errno 32] Broken pipe

2021-05-07 16:40:11,940 - gravity_core.wlogger - ERROR - Traceback (most recent call last):
  File "/home/qodex/Gravity_core_export/gravity_core/wlistener.py", line 102, in broadcastMsgSend
    conn.send(msg)
BrokenPipeError: [Errno 32] Broken pipe

2021-05-07 16:40:27,580 - gravity_core.wlogger - ERROR - Traceback (most recent call last):
  File "/home/qodex/Gravity_core_export/gravity_core/wlistener.py", line 102, in broadcastMsgSend
    conn.send(msg)
BrokenPipeError: [Errno 32] Broken pipe

2021-05-08 10:14:12,479 - gravity_core.wlogger - ERROR - Traceback (most recent call last):
  File "/home/qodex/Gravity_core_export/gravity_core/wlistener.py", line 102, in broadcastMsgSend
    conn.send(msg)
BrokenPipeError: [Errno 32] Broken pipe

2021-05-08 10:14:12,480 - gravity_core.wlogger - ERROR - Traceback (most recent call last):
  File "/home/qodex/Gravity_core_export/gravity_core/wlistener.py", line 102, in broadcastMsgSend
    conn.send(msg)
BrokenPipeError: [Errno 32] Broken pipe

2021-05-08 10:14:12,481 - gravity_core.wlogger - ERROR - Traceback (most recent call last):
  File "/home/qodex/Gravity_core_export/gravity_core/wlistener.py", line 102, in broadcastMsgSend
    conn.send(msg)
BrokenPipeError: [Errno 32] Broken pipe

2021-05-08 10:14:12,482 - gravity_core.wlogger - ERROR - Traceback (most recent call last):
  File "/home/qodex/Gravity_core_export/gravity_core/wlistener.py", line 102, in broadcastMsgSend
    conn.send(msg)
BrokenPipeError: [Errno 32] Broken pipe

2021-05-08 10:14:12,497 - gravity_core.wlogger - ERROR - Traceback (most recent call last):
  File "/home/qodex/Gravity_core_export/gravity_core/wlistener.py", line 102, in broadcastMsgSend
    conn.send(msg)
BrokenPipeError: [Errno 32] Broken pipe

2021-05-08 10:14:12,498 - gravity_core.wlogger - ERROR - Traceback (most recent call last):
  File "/home/qodex/Gravity_core_export/gravity_core/wlistener.py", line 102, in broadcastMsgSend
    conn.send(msg)
BrokenPipeError: [Errno 32] Broken pipe

2021-05-08 10:14:12,500 - gravity_core.wlogger - ERROR - Traceback (most recent call last):
  File "/home/qodex/Gravity_core_export/gravity_core/wlistener.py", line 102, in broadcastMsgSend
    conn.send(msg)
BrokenPipeError: [Errno 32] Broken pipe

2021-05-08 10:14:12,500 - gravity_core.wlogger - ERROR - Traceback (most recent call last):
  File "/home/qodex/Gravity_core_export/gravity_core/wlistener.py", line 102, in broadcastMsgSend
    conn.send(msg)
BrokenPipeError: [Errno 32] Broken pipe

2021-05-08 10:14:12,501 - gravity_core.wlogger - ERROR - Traceback (most recent call last):
  File "/home/qodex/Gravity_core_export/gravity_core/wlistener.py", line 102, in broadcastMsgSend
    conn.send(msg)
BrokenPipeError: [Errno 32] Broken pipe

2021-05-08 10:14:12,502 - gravity_core.wlogger - ERROR - Traceback (most recent call last):
  File "/home/qodex/Gravity_core_export/gravity_core/wlistener.py", line 102, in broadcastMsgSend
    conn.send(msg)
BrokenPipeError: [Errno 32] Broken pipe

2021-05-08 10:14:12,502 - gravity_core.wlogger - ERROR - Traceback (most recent call last):
  File "/home/qodex/Gravity_core_export/gravity_core/wlistener.py", line 102, in broadcastMsgSend
    conn.send(msg)
BrokenPipeError: [Errno 32] Broken pipe

2021-05-08 10:14:12,502 - gravity_core.wlogger - ERROR - Traceback (most recent call last):
  File "/home/qodex/Gravity_core_export/gravity_core/wlistener.py", line 102, in broadcastMsgSend
    conn.send(msg)
BrokenPipeError: [Errno 32] Broken pipe

